Workbook

Sheet 겉지
A1: 어브코스 급여명세서
A2: 순번 | B2: 이름 | C2: 금액 | D2: 급여대장 | E2: 확인 | F2: 비고
A3: 1 | B3: =김향숙!T21 -> 김향숙 | C3: =김향숙!T17 -> -0.46 | D3: 0 | E3: =C3-D3 -> -0.46 | F3: 선지급
A4: 2 | B4: =이영수!T21 -> 이영수 | C4: =이영수!T17 -> -0.42 | D4: 0 | E4: =C4-D4 -> -0.42 | F4: 선지급
A5: 3 | B5: =이미영A!T21 -> 이미영 | C5: =이미영A!T17 -> 0.16 | D5: 0 | E5: =C5-D5 -> 0.16 | F5: 선지급
A6: 4 | B6: =윤선희!T21 -> 윤선희 | C6: =윤선희!T17 -> 0.14 | D6: 0 | E6: =C6-D6 -> 0.14 | F6: 선지급
A7: 5 | B7: =또아!T21 -> 또아 | C7: =또아!T17 -> 0 | D7: 0 | E7: =C7-D7 -> 0 | F7: 선지급
A8: 6 | B8: =김봉화!T21 -> 김봉화 | C8: =김봉화!T17 -> 0.36 | D8: 0 | E8: =C8-D8 -> 0.36 | F8: 선지급
A9: 7 | B9: =이윤진!T21 -> 이윤진 | C9: =이윤진!T17 -> -0.46 | D9: 0 | E9: =C9-D9 -> -0.46 | F9: 선지급
A10: 8 | B10: =이윤영!T21 -> 이윤영 | C10: =이윤영!T17 -> -0.32 | D10: 0 | E10: =C10-D10 -> -0.32 | F10: 선지급
A11: 9 | B11: =김성실!T21 -> 김성실 | C11: =김성실!T17 -> 0.26 | D11: 0 | E11: =C11-D11 -> 0.26 | F11: 선지급
A12: 10 | B12: =박승미!T21 -> 박승미 | C12: =박승미!T17 -> 0.4 | D12: 0 | E12: =C12-D12 -> 0.4 | F12: 선지급
A13: 11 | B13: =김수희!T21 -> 김수희 | C13: =김수희!T17 -> 0 | D13: 0 | E13: =C13-D13 -> 0 | F13: 선지급
A14: 12 | B14: =설홍매!T21 -> 설홍매 | C14: =설홍매!T17 -> -0.46 | D14: 0 | E14: =C14-D14 -> -0.46 | F14: 선지급
A15: 13 | B15: =김구연!T21 -> 김구연 | C15: =김구연!T17 -> 0 | D15: 0 | E15: =C15-D15 -> 0 | F15: 선지급
A16: 14 | B16: =김현순!T21 -> 김현순 | C16: =김현순!T17 -> 2598213 | D16: 2598213 | E16: =C16-D16 -> 0
A17: 15 | B17: =장희숙!T21 -> 장희숙 | C17: =장희숙!T17 -> 2339057 | D17: 2339057 | E17: =C17-D17 -> 0
A18: 16 | B18: =김수정B!T21 -> 김수정 | C18: =김수정B!T17 -> 2290784.3 | D18: 2290784.3 | E18: =C18-D18 -> 0
A19: 17 | B19: =박서원B!T21 -> 박서원 | C19: =박서원B!T17 -> 2533346.6 | D19: 2533346.6 | E19: =C19-D19 -> 0
A20: 18 | B20: =최삼순!T21 -> 최삼순 | C20: =최삼순!T17 -> 2496484.6 | D20: 2496484.6 | E20: =C20-D20 -> 0
A21: 19 | B21: =프라타레네린!T21 -> 프라타레네린 | C21: =프라타레네린!T17 -> 2087327.5 | D21: 2087327.5 | E21: =C21-D21 -> 0
A22: 20 | B22: =육은심!T21 -> 육은심 | C22: =육은심!T17 -> 2446587.4 | D22: 2446587.4 | E22: =C22-D22 -> 0
A23: 21 | B23: =김수현!T21 -> 김수현 | C23: =김수현!T17 -> 2055455.2 | D23: 2055455.2 | E23: =C23-D23 -> 0
A24: 22 | B24: =한계숙!T21 -> 한계숙 | C24: =한계숙!T17 -> -0.32 | D24: 0 | E24: =C24-D24 -> -0.32 | F24: 선지급
A25: 23 | B25: =풍춘향!T21 -> 풍춘향 | C25: =풍춘향!T17 -> 2566340.6 | D25: 2566340.6 | E25: =C25-D25 -> 0
A26: 24 | B26: =유지원!T21 -> 유지원 | C26: =유지원!T17 -> 0 | D26: 0 | E26: =C26-D26 -> 0 | F26: 선지급
A27: 25 | B27: =김연순!T21 -> 김연순 | C27: =김연순!T17 -> 2446587.4 | D27: 2446587.4 | E27: =C27-D27 -> 0
A28: 26 | B28: =지미경!T21 -> 지미경 | C28: =지미경!T17 -> 2438541.9 | D28: 2438541.9 | E28: =C28-D28 -> 0
A29: 27 | B29: =트란티남!T21 -> 쩐티남 | C29: =트란티남!T17 -> 2534468.3 | D29: 2534468.3 | E29: =C29-D29 -> 0
A30: 28 | B30: =박혜선!T21 -> 박혜선 | C30: =박혜선!T17 -> 2819191.8 | D30: 2819191.8 | E30: =C30-D30 -> 0
A31: 29 | B31: =이수진!T21 -> 이수진 | C31: =이수진!T17 -> 2912023.8 | D31: 2912023.8 | E31: =C31-D31 -> 0
A32: 30 | B32: =강명옥!T21 -> 강명옥 | C32: =강명옥!T17 -> 2255044 | D32: 2255044 | E32: =C32-D32 -> 0
A33: 31 | B33: =최춘자!T21 -> 최춘자 | C33: =최춘자!T17 -> 2666715.2 | D33: 2666715.2 | E33: =C33-D33 -> 0
A34: 32 | B34: =레티탐!T21 -> 레티탐 | C34: =레티탐!T17 -> 2819191.8 | D34: 2819191.8 | E34: =C34-D34 -> 0
A35: 33 | B35: =노미순!T21 -> 노미순 | C35: =노미순!T17 -> 2650044.2 | D35: 2650044.2 | E35: =C35-D35 -> 0
A36: 34 | B36: =한서현!T21 -> 한서현 | C36: =한서현!T17 -> 2566340.6 | D36: 2566340.6 | E36: =C36-D36 -> 0
A37: 35 | B37: =응웬티회!T21 -> 응웬티회 | C37: =응웬티회!T17 -> 2095373 | D37: 2095373 | E37: =C37-D37 -> 0
A38: 36 | B38: =정오례!T21 -> 정오례 | C38: =정오례!T17 -> 2326834.1 | D38: 2326834.1 | E38: =C38-D38 -> 0
A39: 37 | B39: =문영!T21 -> 문영 | C39: =문영!T17 -> 2318788.6 | D39: 2318788.6 | E39: =C39-D39 -> 0
A40: 38 | B40: =박정희!T21 -> 박정희 | C40: =박정희!T17 -> 2534468.3 | D40: 2534468.3 | E40: =C40-D40 -> 0
...

Sheet 김향숙
B1: 어브코스
B3: 급 여 | N3: 세 액 및 공 제
B4: 기 본 급 | H4: =AJ26 -> 190 | K4: =H4*10320 -> 1960800 | N4: 갑 근 세
B5: 잔업수당 | H5: =AJ27 -> 12 | K5: =H5*10320*1.5 -> 185760 | N5: 소 득 세 | T5: =H17*3.3% -> 90275.46
B6: 휴일수당 | K6: =H6*10320*1.5 -> 0 | N6: 건 강 보 험
B7: 특근수당 | H7: =AJ28 -> 32 | K7: =H7*10320*1.5 -> 495360 | N7: 장기요양
B8: 심야수당 | H8: =AJ29 -> 0 | K8: =ROUNDDOWN(H8*10320*0.5,-1) -> 0 | N8: 국 민 연 금
B9: 지각/조퇴 | N9: 공과금
B10: 교대주휴 | K10: =10320*H10 -> 0 | N10: 가 불 금
B11: 만근수당 | N11: 선지급 | T11: 2645345
B12: 상여금 | H12: 81700
B13: 간식대 | H13: 12000
N16: 공 제 총 액 | T16: =SUM(T4:Y12) -> 2735620.5
B17: 급 여 총 액 | H17: =SUM(K4,K5,K6,K7,K8,K9,K10,H11,H12,H13,H14,H15,H16) -> 2735620 | N17: 실 수 령 액 | T17: =H17-T16 -> -0.46
N19: 한 달 동안 수고 많으셨습니다 ^^
P21: 이름 : | T21: 김향숙
B24: 이름 | C24: 구분 | D24: 1 | E24: 2 | F24: 3 | G24: 4 | H24: 5 | I24: 6 | J24: 7 | K24: 8 | L24: 9 | M24: 10 | N24: 11 | O24: 12 | P24: 13 | Q24: 14 | R24: 15 | S24: 16 | T24: 17 | U24: 18 | V24: 19 | W24: 20 | X24: 21 | Y24: 22 | Z24: 23 | AA24: 24 | AB24: 25 | AC24: 26 | AD24: 27 | AE24: 28 | AI24: 소급 | AJ24: 합계
D25: 일 | E25: 월 | F25: 화 | G25: 수 | H25: 목 | I25: 금 | J25: 토 | K25: 일 | L25: 월 | M25: 화 | N25: 수 | O25: 목 | P25: 금 | Q25: 토 | R25: 일 | S25: 월 | T25: 화 | U25: 수 | V25: 목 | W25: 금 | X25: 토 | Y25: 일 | Z25: 월 | AA25: 화 | AB25: 수 | AC25: 목 | AD25: 금 | AE25: 토
B26: =T21 -> 김향숙 | C26: 기본 | D26: 8 | E26: 6 | F26: 8 | G26: 8 | H26: 8 | I26: 8 | K26: 8 | L26: 8 | M26: 8 | N26: 8 | O26: 8 | P26: 8 | R26: 8 | S26: 8 | T26: 8 | U26: 8 | V26: 8 | W26: 8 | Y26: 8 | Z26: 8 | AA26: 8 | AB26: 8 | AC26: 8 | AD26: 8 | AJ26: =SUM(D26:AI26) -> 190
C27: 연장 | F27: 2 | G27: 2 | H27: 2 | L27: 2 | M27: 2 | O27: 2 | AJ27: =SUM(D27:AI27) -> 12
C28: 주특 | J28: 8 | Q28: 8 | X28: 8 | AE28: 8 | AJ28: =SUM(D28:AI28) -> 32
C29: 특잔 | AJ29: =SUM(D29:AI29) -> 0
C30: 심야 | AJ30: =SUM(D30:AI30) -> 0
C31: 근태 | T31: 설날 | Z31: 연차 | AJ31: 계

Sheet 이영수
B1: 어브코스
B3: 급 여 | N3: 세 액 및 공 제
B4: 기 본 급 | H4: =AJ26 -> 190 | K4: =H4*10320 -> 1960800 | N4: 갑 근 세
B5: 잔업수당 | H5: =AJ27 -> 14 | K5: =H5*10320*1.5 -> 216720 | N5: 소 득 세 | T5: =H17*3.3% -> 87276.42
B6: 휴일수당 | K6: =H6*10320*1.5 -> 0 | N6: 건 강 보 험
B7: 특근수당 | H7: =AJ28 -> 24 | K7: =H7*10320*1.5 -> 371520 | N7: 장기요양
B8: 심야수당 | H8: =AJ29 -> 0 | K8: =ROUNDDOWN(H8*10320*0.5,-1) -> 0 | N8: 국 민 연 금
B9: 지각/조퇴 | N9: 공과금
B10: 교대주휴 | K10: =10320*H10 -> 0 | N10: 가 불 금 | T10: 1546814
B11: 만근수당 | N11: 선지급 | T11: 1010650
B12: 상여금 | H12: 81700
B13: 간식대 | H13: 14000
N16: 공 제 총 액 | T16: =SUM(T4:Y11) -> 2644740.4
B17: 급 여 총 액 | H17: =SUM(K4,K5,K6,K7,K8,K9,K10,H11,H12,H13,H14,H15,H16) -> 2644740 | N17: 실 수 령 액 | T17: =H17-T16 -> -0.42
N19: 한 달 동안 수고 많으셨습니다 ^^
P21: 이름 : | T21: 이영수
B24: 이름 | C24: 구분 | D24: 1 | E24: 2 | F24: 3 | G24: 4 | H24: 5 | I24: 6 | J24: 7 | K24: 8 | L24: 9 | M24: 10 | N24: 11 | O24: 12 | P24: 13 | Q24: 14 | R24: 15 | S24: 16 | T24: 17 | U24: 18 | V24: 19 | W24: 20 | X24: 21 | Y24: 22 | Z24: 23 | AA24: 24 | AB24: 25 | AC24: 26 | AD24: 27 | AE24: 28 | AI24: 소급 | AJ24: 합계
D25: 일 | E25: 월 | F25: 화 | G25: 수 | H25: 목 | I25: 금 | J25: 토 | K25: 일 | L25: 월 | M25: 화 | N25: 수 | O25: 목 | P25: 금 | Q25: 토 | R25: 일 | S25: 월 | T25: 화 | U25: 수 | V25: 목 | W25: 금 | X25: 토 | Y25: 일 | Z25: 월 | AA25: 화 | AB25: 수 | AC25: 목 | AD25: 금 | AE25: 토
B26: =T21 -> 이영수 | C26: 기본 | D26: 8 | E26: 6 | F26: 8 | G26: 8 | H26: 8 | I26: 8 | K26: 8 | L26: 8 | M26: 8 | N26: 8 | O26: 8 | P26: 8 | R26: 8 | S26: 8 | T26: 8 | U26: 8 | V26: 8 | W26: 8 | Y26: 8 | Z26: 8 | AA26: 8 | AB26: 8 | AC26: 8 | AD26: 8 | AJ26: =SUM(D26:AI26) -> 190
C27: 연장 | F27: 2 | G27: 2 | H27: 2 | L27: 2 | M27: 2 | O27: 2 | AD27: 2 | AJ27: =SUM(D27:AI27) -> 14
C28: 주특 | J28: 8 | Q28: 8 | AE28: 8 | AJ28: =SUM(D28:AI28) -> 24
C29: 특잔 | AJ29: =SUM(D29:AI29) -> 0
C30: 심야 | AJ30: =SUM(D30:AI30) -> 0
C31: 근태 | T31: 설날 | AJ31: 계

Sheet 이미영A
B1: 어브코스
B3: 급 여 | N3: 세 액 및 공 제
B4: 기 본 급 | H4: =AJ26 -> 188 | K4: =H4*10320 -> 1940160 | N4: 갑 근 세
B5: 잔업수당 | H5: =AJ27 -> 10 | K5: =H5*10320*1.5 -> 154800 | N5: 소 득 세 | T5: =H17*3.3% -> 80304.84
B6: 휴일수당 | K6: =H6*10320*1.5 -> 0 | N6: 건 강 보 험
B7: 특근수당 | H7: =AJ28 -> 16 | K7: =H7*10320*1.5 -> 247680 | N7: 장기요양
B8: 심야수당 | H8: =AJ29 -> 0 | K8: =ROUNDDOWN(H8*10320*0.5,-1) -> 0 | N8: 국 민 연 금
B9: 지각/조퇴 | N9: 공과금
B10: 교대주휴 | K10: =10320*H10 -> 0 | N10: 가 불 금 | T10: 1387143
B11: 만근수당 | N11: 선지급 | T11: 966032
B12: 상여금 | H12: 80840
B13: 간식대 | H13: 10000
N16: 공 제 총 액 | T16: =SUM(T4:Y12) -> 2433479.8
B17: 급 여 총 액 | H17: =SUM(K4,K5,K6,K7,K8,K9,K10,H11,H12,H13,H14,H15,H16) -> 2433480 | N17: 실 수 령 액 | T17: =H17-T16 -> 0.16
N19: 한 달 동안 수고 많으셨습니다 ^^
P21: 이름 : | T21: 이미영
B24: 이름 | C24: 구분 | D24: 1 | E24: 2 | F24: 3 | G24: 4 | H24: 5 | I24: 6 | J24: 7 | K24: 8 | L24: 9 | M24: 10 | N24: 11 | O24: 12 | P24: 13 | Q24: 14 | R24: 15 | S24: 16 | T24: 17 | U24: 18 | V24: 19 | W24: 20 | X24: 21 | Y24: 22 | Z24: 23 | AA24: 24 | AB24: 25 | AC24: 26 | AD24: 27 | AE24: 28 | AI24: 소급 | AJ24: 합계
D25: 일 | E25: 월 | F25: 화 | G25: 수 | H25: 목 | I25: 금 | J25: 토 | K25: 일 | L25: 월 | M25: 화 | N25: 수 | O25: 목 | P25: 금 | Q25: 토 | R25: 일 | S25: 월 | T25: 화 | U25: 수 | V25: 목 | W25: 금 | X25: 토 | Y25: 일 | Z25: 월 | AA25: 화 | AB25: 수 | AC25: 목 | AD25: 금 | AE25: 토
B26: =T21 -> 이미영 | C26: 기본 | D26: 8 | E26: 6 | F26: 8 | G26: 8 | H26: 8 | I26: 8 | K26: 8 | L26: 8 | M26: 8 | N26: 8 | O26: 6 | P26: 8 | R26: 8 | S26: 8 | T26: 8 | U26: 8 | V26: 8 | W26: 8 | Y26: 8 | Z26: 8 | AA26: 8 | AB26: 8 | AC26: 8 | AD26: 8 | AJ26: =SUM(D26:AI26) -> 188
C27: 연장 | F27: 2 | G27: 2 | H27: 2 | L27: 2 | M27: 2 | AJ27: =SUM(D27:AI27) -> 10
C28: 주특 | J28: 8 | AE28: 8 | AJ28: =SUM(D28:AI28) -> 16
C29: 특잔 | AJ29: =SUM(D29:AI29) -> 0
C30: 심야 | AJ30: =SUM(D30:AI30) -> 0
C31: 근태 | O31: 조퇴 | P31: 연차 | T31: 설날 | V31: 연차 | W31: 연차 | AJ31: 계

Sheet 윤선희
B1: 어브코스
B3: 급 여 | N3: 세 액 및 공 제
B4: 기 본 급 | H4: =AJ26 -> 190 | K4: =H4*10320 -> 1960800 | N4: 갑 근 세
B5: 잔업수당 | H5: =AJ27 -> 4 | K5: =H5*10320*1.5 -> 61920 | N5: 소 득 세 | T5: =H17*3.3% -> 69577.86
B6: 휴일수당 | K6: =H6*10320*1.5 -> 0 | N6: 건 강 보 험
B7: 특근수당 | H7: =AJ28 -> 0 | K7: =H7*10320*1.5 -> 0 | N7: 장기요양
B8: 심야수당 | H8: =AJ29 -> 0 | K8: =ROUNDDOWN(H8*10320*0.5,-1) -> 0 | N8: 국 민 연 금
B9: 지각/조퇴 | N9: 공과금
B10: 교대주휴 | K10: =10320*H10 -> 0 | N10: 가 불 금
B11: 만근수당 | N11: 선지급 | T11: 2038842
B12: 상여금 | H12: 81700
B13: 간식대 | H13: 4000
N16: 공 제 총 액 | T16: =SUM(T4:Y11) -> 2108419.9
B17: 급 여 총 액 | H17: =SUM(K4,K5,K6,K7,K8,K9,K10,H11,H12,H13,H14,H15,H16) -> 2108420 | N17: 실 수 령 액 | T17: =H17-T16 -> 0.14
N19: 한 달 동안 수고 많으셨습니다 ^^
P21: 이름 : | T21: 윤선희
B24: 이름 | C24: 구분 | D24: 1 | E24: 2 | F24: 3 | G24: 4 | H24: 5 | I24: 6 | J24: 7 | K24: 8 | L24: 9 | M24: 10 | N24: 11 | O24: 12 | P24: 13 | Q24: 14 | R24: 15 | S24: 16 | T24: 17 | U24: 18 | V24: 19 | W24: 20 | X24: 21 | Y24: 22 | Z24: 23 | AA24: 24 | AB24: 25 | AC24: 26 | AD24: 27 | AE24: 28 | AI24: 소급 | AJ24: 합계
D25: 일 | E25: 월 | F25: 화 | G25: 수 | H25: 목 | I25: 금 | J25: 토 | K25: 일 | L25: 월 | M25: 화 | N25: 수 | O25: 목 | P25: 금 | Q25: 토 | R25: 일 | S25: 월 | T25: 화 | U25: 수 | V25: 목 | W25: 금 | X25: 토 | Y25: 일 | Z25: 월 | AA25: 화 | AB25: 수 | AC25: 목 | AD25: 금 | AE25: 토
B26: =T21 -> 윤선희 | C26: 기본 | D26: 8 | E26: 6 | F26: 8 | G26: 8 | H26: 8 | I26: 8 | K26: 8 | L26: 8 | M26: 8 | N26: 8 | O26: 8 | P26: 8 | R26: 8 | S26: 8 | T26: 8 | U26: 8 | V26: 8 | W26: 8 | Y26: 8 | Z26: 8 | AA26: 8 | AB26: 8 | AC26: 8 | AD26: 8 | AJ26: =SUM(D26:AI26) -> 190
C27: 연장 | G27: 2 | O27: 2 | AJ27: =SUM(D27:AI27) -> 4
C28: 주특 | AJ28: =SUM(D28:AI28) -> 0
C29: 특잔 | AJ29: =SUM(D29:AI29) -> 0
C30: 심야 | AJ30: =SUM(D30:AI30) -> 0
C31: 근태 | T31: 설날 | V31: 연차 | W31: 연차 | Z31: 연차 | AJ31: 계

Sheet 또아
B1: 어브코스
B3: 급 여 | N3: 세 액 및 공 제
B4: 기 본 급 | H4: =AJ26 -> 144 | K4: =H4*10320 -> 1486080 | N4: 소득세 | T4: =ROUNDDOWN(((H17/7)-150000)*2.7%,-1)*7 -> 24570
B5: 잔업수당 | H5: =AJ27 -> 10 | K5: =H5*10320*1.5 -> 154800 | N5: 지방소득세 | T5: =ROUNDDOWN(T4*10%,-1) -> 2450
B6: 휴일수당 | K6: =H6*10320*1.5 -> 0 | N6: 건 강 보 험
B7: 특근수당 | H7: =AJ28 -> 16 | K7: =H7*10320*1.5 -> 247680 | N7: 장기요양
B8: 심야수당 | H8: =AJ29 -> 0 | K8: =ROUNDDOWN(H8*10320*0.5,-1) -> 0 | N8: 국 민 연 금
B9: 지각/조퇴 | N9: 고용보험 | T9: =ROUNDDOWN(H17*0.9%,-1) -> 17640
B10: 교대주휴 | K10: =10320*H10 -> 0 | N10: 가 불 금
B11: 만근수당 | N11: 선지급 | T11: 1915820
B12: 상여금 | H12: 61920
B13: 간식대 | H13: 10000
N16: 공 제 총 액 | T16: =SUM(T4:Y11) -> 1960480
B17: 급 여 총 액 | H17: =SUM(K4,K5,K6,K7,K8,K9,K10,H11,H12,H13,H14,H15,H16) -> 1960480 | N17: 실 수 령 액 | T17: =H17-T16 -> 0
N19: 한 달 동안 수고 많으셨습니다 ^^
P21: 이름 : | T21: 또아
B24: 이름 | C24: 구분 | D24: 1 | E24: 2 | F24: 3 | G24: 4 | H24: 5 | I24: 6 | J24: 7 | K24: 8 | L24: 9 | M24: 10 | N24: 11 | O24: 12 | P24: 13 | Q24: 14 | R24: 15 | S24: 16 | T24: 17 | U24: 18 | V24: 19 | W24: 20 | X24: 21 | Y24: 22 | Z24: 23 | AA24: 24 | AB24: 25 | AC24: 26 | AD24: 27 | AE24: 28 | AI24: 소급 | AJ24: 합계
D25: 일 | E25: 월 | F25: 화 | G25: 수 | H25: 목 | I25: 금 | J25: 토 | K25: 일 | L25: 월 | M25: 화 | N25: 수 | O25: 목 | P25: 금 | Q25: 토 | R25: 일 | S25: 월 | T25: 화 | U25: 수 | V25: 목 | W25: 금 | X25: 토 | Y25: 일 | Z25: 월 | AA25: 화 | AB25: 수 | AC25: 목 | AD25: 금 | AE25: 토
B26: =T21 -> 또아 | C26: 기본 | D26: 8 | E26: 8 | F26: 8 | G26: 8 | H26: 8 | I26: 8 | K26: 8 | S26: 8 | T26: 8 | U26: 8 | V26: 8 | W26: 8 | Y26: 8 | Z26: 8 | AA26: 8 | AB26: 8 | AC26: 8 | AD26: 8 | AJ26: =SUM(D26:AI26) -> 144
C27: 연장 | E27: 2 | F27: 2 | G27: 2 | H27: 2 | AD27: 2 | AJ27: =SUM(D27:AI27) -> 10
C28: 주특 | J28: 8 | AE28: 8 | AJ28: =SUM(D28:AI28) -> 16
C29: 특잔 | AJ29: =SUM(D29:AI29) -> 0
C30: 심야 | AJ30: =SUM(D30:AI30) -> 0
C31: 근태 | L31: 결근 | M31: 결근 | N31: 결근 | O31: 결근 | P31: 결근 | T31: 설날 | V31: 연차 | W31: 연차 | AJ31: 계

Sheet 김봉화
B1: 어브코스
B3: 급 여 | N3: 세 액 및 공 제
B4: 기 본 급 | H4: =AJ26 -> 192 | K4: =H4*10320 -> 1981440 | N4: 갑 근 세
B5: 잔업수당 | H5: =AJ27 -> 17 | K5: =H5*10320*1.5 -> 263160 | N5: 소 득 세 | T5: =H17*3.3% -> 96395.64
B6: 휴일수당 | K6: =H6*10320*1.5 -> 0 | N6: 건 강 보 험
B7: 특근수당 | H7: =AJ28 -> 32 | K7: =H7*10320*1.5 -> 495360 | N7: 장기요양
B8: 심야수당 | H8: =AJ29 -> 0 | K8: =ROUNDDOWN(H8*10320*0.5,-1) -> 0 | N8: 국 민 연 금
B9: 지각/조퇴 | N9: 공과금
B10: 교대주휴 | K10: =10320*H10 -> 0 | N10: 가 불 금
B11: 만근수당 | N11: 선지급 | T11: 2824684
B12: 상여금 | H12: 165120
B13: 간식대 | H13: 16000
N16: 공 제 총 액 | T16: =SUM(T4:Y11) -> 2921079.6
B17: 급 여 총 액 | H17: =SUM(K4,K5,K6,K7,K8,K9,K10,H11,H12,H13,H14,H15,H16) -> 2921080 | N17: 실 수 령 액 | T17: =H17-T16 -> 0.36
N19: 한 달 동안 수고 많으셨습니다 ^^
P21: 이름 : | T21: 김봉화
B24: 이름 | C24: 구분 | D24: 1 | E24: 2 | F24: 3 | G24: 4 | H24: 5 | I24: 6 | J24: 7 | K24: 8 | L24: 9 | M24: 10 | N24: 11 | O24: 12 | P24: 13 | Q24: 14 | R24: 15 | S24: 16 | T24: 17 | U24: 18 | V24: 19 | W24: 20 | X24: 21 | Y24: 22 | Z24: 23 | AA24: 24 | AB24: 25 | AC24: 26 | AD24: 27 | AE24: 28 | AI24: 소급 | AJ24: 합계
D25: 일 | E25: 월 | F25: 화 | G25: 수 | H25: 목 | I25: 금 | J25: 토 | K25: 일 | L25: 월 | M25: 화 | N25: 수 | O25: 목 | P25: 금 | Q25: 토 | R25: 일 | S25: 월 | T25: 화 | U25: 수 | V25: 목 | W25: 금 | X25: 토 | Y25: 일 | Z25: 월 | AA25: 화 | AB25: 수 | AC25: 목 | AD25: 금 | AE25: 토
B26: =T21 -> 김봉화 | C26: 기본 | D26: 8 | E26: 8 | F26: 8 | G26: 8 | H26: 8 | I26: 8 | K26: 8 | L26: 8 | M26: 8 | N26: 8 | O26: 8 | P26: 8 | R26: 8 | S26: 8 | T26: 8 | U26: 8 | V26: 8 | W26: 8 | Y26: 8 | Z26: 8 | AA26: 8 | AB26: 8 | AC26: 8 | AD26: 8 | AJ26: =SUM(D26:AI26) -> 192
C27: 연장 | E27: 2 | F27: 2 | G27: 2 | H27: 2 | L27: 2 | M27: 2 | O27: 2 | V27: 1 | AD27: 2 | AJ27: =SUM(D27:AI27) -> 17
C28: 주특 | J28: 8 | Q28: 8 | X28: 8 | AE28: 8 | AJ28: =SUM(D28:AI28) -> 32
C29: 특잔 | AJ29: =SUM(D29:AI29) -> 0
C30: 심야 | AJ30: =SUM(D30:AI30) -> 0
C31: 근태 | T31: 설날 | AJ31: 계

Sheet 이윤진
B1: 어브코스
B3: 급 여 | N3: 세 액 및 공 제
B4: 기 본 급 | H4: =AJ26 -> 190 | K4: =H4*10320 -> 1960800 | N4: 갑 근 세
B5: 잔업수당 | H5: =AJ27 -> 12 | K5: =H5*10320*1.5 -> 185760 | N5: 소 득 세 | T5: =H17*3.3% -> 90275.46
B6: 휴일수당 | K6: =H6*10320*1.5 -> 0 | N6: 건 강 보 험
B7: 특근수당 | H7: =AJ28 -> 32 | K7: =H7*10320*1.5 -> 495360 | N7: 장기요양
B8: 심야수당 | H8: =AJ29 -> 0 | K8: =ROUNDDOWN(H8*10320*0.5,-1) -> 0 | N8: 국 민 연 금
B9: 교대주휴 | N9: 고용보험
B10: 부서수당 | N10: 가 불 금 | T10: 1516876
B11: 만근수당 | N11: 선지급 | T11: 1128469
B12: 상여금 | H12: 81700
B13: 간식대 | H13: 12000
N16: 공 제 총 액 | T16: =SUM(T4:Y11) -> 2735620.5
B17: 급 여 총 액 | H17: =SUM(K4,K5,K6,K7,K8,K9,H10,H11,H12,H13,H14,H15,H16) -> 2735620 | N17: 실 수 령 액 | T17: =H17-T16 -> -0.46
N19: 한 달 동안 수고 많으셨습니다 ^^
P21: 이름 : | T21: 이윤진
B24: 이름 | C24: 구분 | D24: 1 | E24: 2 | F24: 3 | G24: 4 | H24: 5 | I24: 6 | J24: 7 | K24: 8 | L24: 9 | M24: 10 | N24: 11 | O24: 12 | P24: 13 | Q24: 14 | R24: 15 | S24: 16 | T24: 17 | U24: 18 | V24: 19 | W24: 20 | X24: 21 | Y24: 22 | Z24: 23 | AA24: 24 | AB24: 25 | AC24: 26 | AD24: 27 | AE24: 28 | AI24: 소급 | AJ24: 합계
D25: 일 | E25: 월 | F25: 화 | G25: 수 | H25: 목 | I25: 금 | J25: 토 | K25: 일 | L25: 월 | M25: 화 | N25: 수 | O25: 목 | P25: 금 | Q25: 토 | R25: 일 | S25: 월 | T25: 화 | U25: 수 | V25: 목 | W25: 금 | X25: 토 | Y25: 일 | Z25: 월 | AA25: 화 | AB25: 수 | AC25: 목 | AD25: 금 | AE25: 토
B26: =T21 -> 이윤진 | C26: 기본 | D26: 8 | E26: 6 | F26: 8 | G26: 8 | H26: 8 | I26: 8 | K26: 8 | L26: 8 | M26: 8 | N26: 8 | O26: 8 | P26: 8 | R26: 8 | S26: 8 | T26: 8 | U26: 8 | V26: 8 | W26: 8 | Y26: 8 | Z26: 8 | AA26: 8 | AB26: 8 | AC26: 8 | AD26: 8 | AJ26: =SUM(D26:AI26) -> 190
C27: 연장 | F27: 2 | G27: 2 | H27: 2 | L27: 2 | M27: 2 | O27: 2 | AJ27: =SUM(D27:AI27) -> 12
C28: 주특 | J28: 8 | Q28: 8 | X28: 8 | AE28: 8 | AJ28: =SUM(D28:AI28) -> 32
C29: 특잔 | AJ29: =SUM(D29:AI29) -> 0
C30: 심야 | AJ30: =SUM(D30:AI30) -> 0
C31: 근태 | T31: 설날 | AJ31: 계

Sheet 이윤영
B1: 어브코스
B3: 급 여 | N3: 세 액 및 공 제
B4: 기 본 급 | H4: =AJ26 -> 192 | K4: =H4*10320 -> 1981440 | N4: 갑 근 세
B5: 잔업수당 | H5: =AJ27 -> 16 | K5: =H5*10320*1.5 -> 247680 | N5: 소 득 세 | T5: =H17*3.3% -> 93160.32
B6: 휴일수당 | K6: =H6*10320*1.5 -> 0 | N6: 건 강 보 험
B7: 특근수당 | H7: =AJ28 -> 32 | K7: =H7*10320*1.5 -> 495360 | N7: 장기요양
B8: 심야수당 | H8: =AJ29 -> 0 | K8: =ROUNDDOWN(H8*10320*0.5,-1) -> 0 | N8: 국 민 연 금
B9: 교대주휴 | N9: 공과금
B10: 지각/조퇴 | N10: 가 불 금
B11: 만근수당 | N11: 선지급 | T11: 2729880
B12: 상여금 | H12: 82560
B13: 간식대 | H13: 16000
N16: 공 제 총 액 | T16: =SUM(T4:Y11) -> 2823040.3
B17: 급 여 총 액 | H17: =SUM(K4,K5,K6,K7,K8,K9,H10,H11,H12,H13,H14,H15,H16) -> 2823040 | N17: 실 수 령 액 | T17: =H17-T16 -> -0.32
N19: 한 달 동안 수고 많으셨습니다 ^^
P21: 이름 : | T21: 이윤영
B24: 이름 | C24: 구분 | D24: 1 | E24: 2 | F24: 3 | G24: 4 | H24: 5 | I24: 6 | J24: 7 | K24: 8 | L24: 9 | M24: 10 | N24: 11 | O24: 12 | P24: 13 | Q24: 14 | R24: 15 | S24: 16 | T24: 17 | U24: 18 | V24: 19 | W24: 20 | X24: 21 | Y24: 22 | Z24: 23 | AA24: 24 | AB24: 25 | AC24: 26 | AD24: 27 | AE24: 28 | AI24: 소급 | AJ24: 합계
D25: 일 | E25: 월 | F25: 화 | G25: 수 | H25: 목 | I25: 금 | J25: 토 | K25: 일 | L25: 월 | M25: 화 | N25: 수 | O25: 목 | P25: 금 | Q25: 토 | R25: 일 | S25: 월 | T25: 화 | U25: 수 | V25: 목 | W25: 금 | X25: 토 | Y25: 일 | Z25: 월 | AA25: 화 | AB25: 수 | AC25: 목 | AD25: 금 | AE25: 토
B26: =T21 -> 이윤영 | C26: 기본 | D26: 8 | E26: 8 | F26: 8 | G26: 8 | H26: 8 | I26: 8 | K26: 8 | L26: 8 | M26: 8 | N26: 8 | O26: 8 | P26: 8 | R26: 8 | S26: 8 | T26: 8 | U26: 8 | V26: 8 | W26: 8 | Y26: 8 | Z26: 8 | AA26: 8 | AB26: 8 | AC26: 8 | AD26: 8 | AJ26: =SUM(D26:AI26) -> 192
C27: 연장 | E27: 2 | F27: 2 | G27: 2 | H27: 2 | L27: 2 | M27: 2 | O27: 2 | AD27: 2 | AJ27: =SUM(D27:AI27) -> 16
C28: 주특 | J28: 8 | Q28: 8 | X28: 8 | AE28: 8 | AJ28: =SUM(D28:AI28) -> 32
C29: 특잔 | AJ29: =SUM(D29:AI29) -> 0
C30: 심야 | AJ30: =SUM(D30:AI30) -> 0
C31: 근태 | T31: 설날 | AJ31: 계

Sheet 김성실
B1: 어브코스
B3: 급 여 | N3: 세 액 및 공 제
B4: 기 본 급 | H4: =AJ26 -> 174 | K4: =H4*10320 -> 1795680 | N4: 갑 근 세
B5: 잔업수당 | H5: =AJ27 -> 12 | K5: =H5*10320*1.5 -> 185760 | N5: 소 득 세 | T5: =H17*3.3% -> 80512.74
B6: 휴일수당 | K6: =H6*10320*1.5 -> 0 | N6: 건 강 보 험
B7: 특근수당 | H7: =AJ28 -> 24 | K7: =H7*10320*1.5 -> 371520 | N7: 장기요양
B8: 심야수당 | H8: =AJ29 -> 0 | K8: =ROUNDDOWN(H8*10320*0.5,-1) -> 0 | N8: 국 민 연 금
B9: 지각/조퇴 | N9: 공과금
B10: 부서수당 | N10: 가 불 금
B11: 만근수당 | N11: 선지급 | T11: 2359267
B12: 상여금 | H12: 74820
B13: 간식대 | H13: 12000
N16: 공 제 총 액 | T16: =SUM(T4:Y11) -> 2439779.7
B17: 급 여 총 액 | H17: =SUM(K4,K5,K6,K7,K8,K9,H10,H11,H12,H13,H14,H15,H16) -> 2439780 | N17: 실 수 령 액 | T17: =H17-T16 -> 0.26
N19: 한 달 동안 수고 많으셨습니다 ^^
P21: 이름 : | T21: 김성실
B24: 이름 | C24: 구분 | D24: 1 | E24: 2 | F24: 3 | G24: 4 | H24: 5 | I24: 6 | J24: 7 | K24: 8 | L24: 9 | M24: 10 | N24: 11 | O24: 12 | P24: 13 | Q24: 14 | R24: 15 | S24: 16 | T24: 17 | U24: 18 | V24: 19 | W24: 20 | X24: 21 | Y24: 22 | Z24: 23 | AA24: 24 | AB24: 25 | AC24: 26 | AD24: 27 | AE24: 28 | AI24: 소급 | AJ24: 합계
D25: 일 | E25: 월 | F25: 화 | G25: 수 | H25: 목 | I25: 금 | J25: 토 | K25: 일 | L25: 월 | M25: 화 | N25: 수 | O25: 목 | P25: 금 | Q25: 토 | R25: 일 | S25: 월 | T25: 화 | U25: 수 | V25: 목 | W25: 금 | X25: 토 | Y25: 일 | Z25: 월 | AA25: 화 | AB25: 수 | AC25: 목 | AD25: 금 | AE25: 토
B26: =T21 -> 김성실 | C26: 기본 | D26: 8 | E26: 6 | F26: 8 | G26: 8 | H26: 8 | I26: 8 | K26: 8 | L26: 8 | M26: 8 | N26: 8 | O26: 8 | P26: 8 | R26: 8 | S26: 8 | T26: 8 | U26: 8 | V26: 8 | W26: 8 | Y26: 8 | Z26: 8 | AA26: 8 | AB26: 8 | AJ26: =SUM(D26:AI26) -> 174
C27: 연장 | F27: 2 | G27: 2 | H27: 2 | L27: 2 | M27: 2 | O27: 2 | AJ27: =SUM(D27:AI27) -> 12
C28: 주특 | J28: 8 | Q28: 8 | X28: 8 | AJ28: =SUM(D28:AI28) -> 24
C29: 특잔 | AJ29: =SUM(D29:AI29) -> 0
C30: 심야 | AJ30: =SUM(D30:AI30) -> 0
C31: 근태 | T31: 설날 | AB31: 퇴사 | AJ31: 계

Sheet 박승미
B1: 어브코스
B3: 급 여 | N3: 세 액 및 공 제
B4: 기 본 급 | H4: =AJ26 -> 192 | K4: =H4*10320 -> 1981440 | N4: 갑 근 세
B5: 잔업수당 | H5: =AJ27 -> 16 | K5: =H5*10320*1.5 -> 247680 | N5: 소 득 세 | T5: =H17*3.3% -> 89073.6
B6: 휴일수당 | K6: =H6*10320*1.5 -> 0 | N6: 건 강 보 험
B7: 특근수당 | H7: =AJ28 -> 24 | K7: =H7*10320*1.5 -> 371520 | N7: 장기요양
B8: 심야수당 | H8: =AJ29 -> 0 | K8: =ROUNDDOWN(H8*10320*0.5,-1) -> 0 | N8: 국 민 연 금
B9: 지각/조퇴 | N9: 공과금
B10: 부서수당 | N10: 가 불 금
B11: 만근수당 | N11: 선지급 | T11: 2610126
B12: 상여금 | H12: 82560
B13: 간식대 | H13: 16000
N16: 공 제 총 액 | T16: =SUM(T4:Y11) -> 2699199.6
B17: 급 여 총 액 | H17: =SUM(K4,K5,K6,K7,K8,K9,H10,H11,H12,H13,H14,H15,H16) -> 2699200 | N17: 실 수 령 액 | T17: =H17-T16 -> 0.4
N19: 한 달 동안 수고 많으셨습니다 ^^
P21: 이름 : | T21: 박승미
B24: 이름 | C24: 구분 | D24: 1 | E24: 2 | F24: 3 | G24: 4 | H24: 5 | I24: 6 | J24: 7 | K24: 8 | L24: 9 | M24: 10 | N24: 11 | O24: 12 | P24: 13 | Q24: 14 | R24: 15 | S24: 16 | T24: 17 | U24: 18 | V24: 19 | W24: 20 | X24: 21 | Y24: 22 | Z24: 23 | AA24: 24 | AB24: 25 | AC24: 26 | AD24: 27 | AE24: 28 | AI24: 소급 | AJ24: 합계
D25: 일 | E25: 월 | F25: 화 | G25: 수 | H25: 목 | I25: 금 | J25: 토 | K25: 일 | L25: 월 | M25: 화 | N25: 수 | O25: 목 | P25: 금 | Q25: 토 | R25: 일 | S25: 월 | T25: 화 | U25: 수 | V25: 목 | W25: 금 | X25: 토 | Y25: 일 | Z25: 월 | AA25: 화 | AB25: 수 | AC25: 목 | AD25: 금 | AE25: 토
B26: =T21 -> 박승미 | C26: 기본 | D26: 8 | E26: 8 | F26: 8 | G26: 8 | H26: 8 | I26: 8 | K26: 8 | L26: 8 | M26: 8 | N26: 8 | O26: 8 | P26: 8 | R26: 8 | S26: 8 | T26: 8 | U26: 8 | V26: 8 | W26: 8 | Y26: 8 | Z26: 8 | AA26: 8 | AB26: 8 | AC26: 8 | AD26: 8 | AJ26: =SUM(D26:AI26) -> 192
C27: 연장 | E27: 2 | F27: 2 | G27: 2 | H27: 2 | L27: 2 | M27: 2 | O27: 2 | AD27: 2 | AJ27: =SUM(D27:AI27) -> 16
C28: 주특 | J28: 8 | Q28: 8 | X28: 8 | AJ28: =SUM(D28:AI28) -> 24
C29: 특잔 | AJ29: =SUM(D29:AI29) -> 0
C30: 심야 | AJ30: =SUM(D30:AI30) -> 0
C31: 근태 | P31: 반차 | T31: 설날 | AJ31: 계

Sheet 김수희
B1: 어브코스
B3: 급 여 | N3: 세 액 및 공 제
B4: 기 본 급 | H4: =AJ26 -> 158 | K4: =H4*10320 -> 1630560 | N4: 갑 근 세
B5: 잔업수당 | H5: =AJ27 -> 0 | K5: =H5*10320*1.5 -> 0 | N5: 소 득 세 | T5: =H17*3.3% -> 94363.5
B6: 휴일수당 | K6: =H6*10320*1.5 -> 0 | N6: 건 강 보 험
B7: 특근수당 | H7: =AJ28 -> 24 | K7: =H7*10320*1.5 -> 371520 | N7: 장기요양
B8: 심야수당 | H8: =AJ29 -> 51 | K8: =ROUNDDOWN(H8*10320*1.5,-1) -> 789480 | N8: 국 민 연 금
B9: 지각/조퇴 | N9: 공과금
B10: 부서수당 | N10: 가 불 금
B11: 만근수당 | N11: 선지급 | T11: 2765137
B12: 상여금 | H12: 67940
B13: 간식대
N16: 공 제 총 액 | T16: =SUM(T4:Y11) -> 2859500.5
B17: 급 여 총 액 | H17: =SUM(K4,K5,K6,K7,K8,K9,H10,H11,H12,H13,H14,H15,H16) -> 2859500 | N17: 실 수 령 액 | T17: =ROUNDDOWN(H17-T16,-1) -> 0
N19: 한 달 동안 수고 많으셨습니다 ^^
P21: 이름 : | T21: 김수희
B24: 이름 | C24: 구분 | D24: 1 | E24: 2 | F24: 3 | G24: 4 | H24: 5 | I24: 6 | J24: 7 | K24: 8 | L24: 9 | M24: 10 | N24: 11 | O24: 12 | P24: 13 | Q24: 14 | R24: 15 | S24: 16 | T24: 17 | U24: 18 | V24: 19 | W24: 20 | X24: 21 | Y24: 22 | Z24: 23 | AA24: 24 | AB24: 25 | AC24: 26 | AD24: 27 | AE24: 28 | AI24: 소급 | AJ24: 합계
D25: 일 | E25: 월 | F25: 화 | G25: 수 | H25: 목 | I25: 금 | J25: 토 | K25: 일 | L25: 월 | M25: 화 | N25: 수 | O25: 목 | P25: 금 | Q25: 토 | R25: 일 | S25: 월 | T25: 화 | U25: 수 | V25: 목 | W25: 금 | X25: 토 | Y25: 일 | Z25: 월 | AA25: 화 | AB25: 수 | AC25: 목 | AD25: 금 | AE25: 토
B26: =T21 -> 김수희 | C26: 기본 | D26: 8 | E26: 6 | F26: 6 | G26: 6 | H26: 6 | I26: 6 | K26: 8 | L26: 6 | M26: 6 | N26: 6 | O26: 6 | P26: 6 | R26: 8 | S26: 8 | T26: 8 | U26: 8 | V26: 6 | W26: 6 | Y26: 8 | Z26: 6 | AA26: 6 | AB26: 6 | AC26: 6 | AD26: 6 | AJ26: =SUM(D26:AI26) -> 158
C27: 연장 | AJ27: =SUM(D27:AI27) -> 0
C28: 주특 | J28: 8 | X28: 8 | AE28: 8 | AJ28: =SUM(D28:AI28) -> 24
C29: 수당 | E29: 3 | F29: 3 | G29: 3 | H29: 3 | I29: 3 | L29: 3 | M29: 3 | N29: 3 | O29: 3 | P29: 3 | V29: 3 | W29: 3 | Z29: 3 | AA29: 3 | AB29: 3 | AC29: 3 | AD29: 3 | AJ29: =SUM(D29:AI29) -> 51
C30: 심야 | AJ30: =SUM(D30:AI30) -> 0
C31: 근태 | T31: 설날 | AJ31: 계

Sheet 설홍매
B1: 어브코스
B3: 급 여 | N3: 세 액 및 공 제
B4: 기 본 급 | H4: =AJ26 -> 190 | K4: =H4*10320 -> 1960800 | N4: 갑 근 세
B5: 잔업수당 | H5: =AJ27 -> 12 | K5: =H5*10320*1.5 -> 185760 | N5: 소 득 세 | T5: =H17*3.3% -> 90275.46
B6: 휴일수당 | K6: =H6*10320*1.5 -> 0 | N6: 건 강 보 험
B7: 특근수당 | H7: =AJ28 -> 32 | K7: =H7*10320*1.5 -> 495360 | N7: 장기요양
B8: 심야수당 | H8: =AJ29 -> 0 | K8: =ROUNDDOWN(H8*10320*0.5,-1) -> 0 | N8: 국 민 연 금
B9: 지각/조퇴 | N9: 공과금
B10: 부서수당 | N10: 가 불 금
B11: 만근수당 | N11: 선지급 | T11: 2645345
B12: 상여금 | H12: 81700
B13: 간식대 | H13: 12000
N16: 공 제 총 액 | T16: =SUM(T4:Y11) -> 2735620.5
B17: 급 여 총 액 | H17: =SUM(K4,K5,K6,K7,K8,K9,H10,H11,H12,H13,H14,H15,H16) -> 2735620 | N17: 실 수 령 액 | T17: =H17-T16 -> -0.46
N19: 한 달 동안 수고 많으셨습니다 ^^
P21: 이름 : | T21: 설홍매
B24: 이름 | C24: 구분 | D24: 1 | E24: 2 | F24: 3 | G24: 4 | H24: 5 | I24: 6 | J24: 7 | K24: 8 | L24: 9 | M24: 10 | N24: 11 | O24: 12 | P24: 13 | Q24: 14 | R24: 15 | S24: 16 | T24: 17 | U24: 18 | V24: 19 | W24: 20 | X24: 21 | Y24: 22 | Z24: 23 | AA24: 24 | AB24: 25 | AC24: 26 | AD24: 27 | AE24: 28 | AI24: 소급 | AJ24: 합계
D25: 일 | E25: 월 | F25: 화 | G25: 수 | H25: 목 | I25: 금 | J25: 토 | K25: 일 | L25: 월 | M25: 화 | N25: 수 | O25: 목 | P25: 금 | Q25: 토 | R25: 일 | S25: 월 | T25: 화 | U25: 수 | V25: 목 | W25: 금 | X25: 토 | Y25: 일 | Z25: 월 | AA25: 화 | AB25: 수 | AC25: 목 | AD25: 금 | AE25: 토
B26: =T21 -> 설홍매 | C26: 기본 | D26: 8 | E26: 6 | F26: 8 | G26: 8 | H26: 8 | I26: 8 | K26: 8 | L26: 8 | M26: 8 | N26: 8 | O26: 8 | P26: 8 | R26: 8 | S26: 8 | T26: 8 | U26: 8 | V26: 8 | W26: 8 | Y26: 8 | Z26: 8 | AA26: 8 | AB26: 8 | AC26: 8 | AD26: 8 | AJ26: =SUM(D26:AI26) -> 190
C27: 연장 | F27: 2 | G27: 2 | H27: 2 | L27: 2 | M27: 2 | O27: 2 | AJ27: =SUM(D27:AI27) -> 12
C28: 주특 | J28: 8 | Q28: 8 | X28: 8 | AE28: 8 | AJ28: =SUM(D28:AI28) -> 32
C29: 특잔 | AJ29: =SUM(D29:AI29) -> 0
C30: 심야 | AJ30: =SUM(D30:AI30) -> 0
C31: 근태 | T31: 설날 | AA31: 연차 | AB31: 연차 | AJ31: 계

Sheet 김구연
B1: 어브코스
B3: 급 여 | N3: 세 액 및 공 제
B4: 기 본 급 | H4: =AJ26 -> 158 | K4: =H4*10320 -> 1630560 | N4: 갑 근 세
B5: 잔업수당 | H5: =AJ27 -> 0 | K5: =H5*10320*1.5 -> 0 | N5: 소 득 세 | T5: =H17*3.3% -> 99709.5
B6: 휴일수당 | K6: =H6*10320*1.5 -> 0 | N6: 건 강 보 험
B7: 특근수당 | H7: =AJ28 -> 24 | K7: =H7*10320*1.5 -> 371520 | N7: 장기요양
B8: 심야수당 | H8: =AJ29 -> 51 | K8: =ROUNDDOWN(H8*10320*1.5,-1) -> 789480 | N8: 국 민 연 금
B9: 지각/조퇴 | N9: 공과금
B10: 부서수당 | N10: 가 불 금
B11: 만근수당 | N11: 선지급 | T11: 2921791
B12: 상여금 | H12: 67940
B13: 간식대 | H13: 162000
N16: 공 제 총 액 | T16: =SUM(T4:Y11) -> 3021500.5
B17: 급 여 총 액 | H17: =SUM(K4,K5,K6,K7,K8,K9,H10,H11,H12,H13,H14,H15,H16) -> 3021500 | N17: 실 수 령 액 | T17: =ROUNDDOWN(H17-T16,-1) -> 0
N19: 한 달 동안 수고 많으셨습니다 ^^
P21: 이름 : | T21: 김구연
B24: 이름 | C24: 구분 | D24: 1 | E24: 2 | F24: 3 | G24: 4 | H24: 5 | I24: 6 | J24: 7 | K24: 8 | L24: 9 | M24: 10 | N24: 11 | O24: 12 | P24: 13 | Q24: 14 | R24: 15 | S24: 16 | T24: 17 | U24: 18 | V24: 19 | W24: 20 | X24: 21 | Y24: 22 | Z24: 23 | AA24: 24 | AB24: 25 | AC24: 26 | AD24: 27 | AE24: 28 | AI24: 소급 | AJ24: 합계
D25: 일 | E25: 월 | F25: 화 | G25: 수 | H25: 목 | I25: 금 | J25: 토 | K25: 일 | L25: 월 | M25: 화 | N25: 수 | O25: 목 | P25: 금 | Q25: 토 | R25: 일 | S25: 월 | T25: 화 | U25: 수 | V25: 목 | W25: 금 | X25: 토 | Y25: 일 | Z25: 월 | AA25: 화 | AB25: 수 | AC25: 목 | AD25: 금 | AE25: 토
B26: =T21 -> 김구연 | C26: 기본 | D26: 8 | E26: 6 | F26: 6 | G26: 6 | H26: 6 | I26: 6 | K26: 8 | L26: 6 | M26: 6 | N26: 6 | O26: 6 | P26: 6 | R26: 8 | S26: 8 | T26: 8 | U26: 8 | V26: 6 | W26: 6 | Y26: 8 | Z26: 6 | AA26: 6 | AB26: 6 | AC26: 6 | AD26: 6 | AJ26: =SUM(D26:AI26) -> 158
C27: 연장 | AJ27: =SUM(D27:AI27) -> 0
C28: 주특 | J28: 8 | Q28: 8 | AE28: 8 | AJ28: =SUM(D28:AI28) -> 24
C29: 수당 | E29: 3 | F29: 3 | G29: 3 | H29: 3 | I29: 3 | L29: 3 | M29: 3 | N29: 3 | O29: 3 | P29: 3 | V29: 3 | W29: 3 | Z29: 3 | AA29: 3 | AB29: 3 | AC29: 3 | AD29: 3 | AJ29: =SUM(D29:AI29) -> 51
C30: 심야 | AJ30: =SUM(D30:AI30) -> 0
C31: 근태 | E31: 연차 | T31: 설날 | AJ31: 계

Sheet 김현순
B1: 어브코스
B3: 급 여 | N3: 세 액 및 공 제
B4: 기 본 급 | H4: =AJ26 -> 190 | K4: =H4*10320 -> 1960800 | N4: 갑 근 세
B5: 잔업수당 | H5: =AJ27 -> 14 | K5: =H5*10320*1.5 -> 216720 | N5: 소 득 세 | T5: =H17*3.3% -> 88667.04
B6: 휴일수당 | K6: =H6*10320*1.5 -> 0 | N6: 건 강 보 험
B7: 특근수당 | H7: =AJ28 -> 32 | K7: =H7*10320*1.5 -> 495360 | N7: 장기요양
B8: 심야수당 | H8: =AJ29 -> 0 | K8: =ROUNDDOWN(H8*10320*0.5,-1) -> 0 | N8: 국 민 연 금
B9: 지각/조퇴 | N9: 공과금
B10: 부서수당 | N10: 가 불 금
B11: 만근수당 | N11: 선지급
B12: 상여금
B13: 간식대 | H13: 14000
N16: 공 제 총 액 | T16: =SUM(T4:Y11) -> 88667.04
B17: 급 여 총 액 | H17: =SUM(K4,K5,K6,K7,K8,K9,H10,H11,H12,H13,H14,H15,H16) -> 2686880 | N17: 실 수 령 액 | T17: =H17-T16 -> 2598213
N19: 한 달 동안 수고 많으셨습니다 ^^
P21: 이름 : | T21: 김현순
B24: 이름 | C24: 구분 | D24: 1 | E24: 2 | F24: 3 | G24: 4 | H24: 5 | I24: 6 | J24: 7 | K24: 8 | L24: 9 | M24: 10 | N24: 11 | O24: 12 | P24: 13 | Q24: 14 | R24: 15 | S24: 16 | T24: 17 | U24: 18 | V24: 19 | W24: 20 | X24: 21 | Y24: 22 | Z24: 23 | AA24: 24 | AB24: 25 | AC24: 26 | AD24: 27 | AE24: 28 | AI24: 소급 | AJ24: 합계
D25: 일 | E25: 월 | F25: 화 | G25: 수 | H25: 목 | I25: 금 | J25: 토 | K25: 일 | L25: 월 | M25: 화 | N25: 수 | O25: 목 | P25: 금 | Q25: 토 | R25: 일 | S25: 월 | T25: 화 | U25: 수 | V25: 목 | W25: 금 | X25: 토 | Y25: 일 | Z25: 월 | AA25: 화 | AB25: 수 | AC25: 목 | AD25: 금 | AE25: 토
B26: =T21 -> 김현순 | C26: 기본 | D26: 8 | E26: 6 | F26: 8 | G26: 8 | H26: 8 | I26: 8 | K26: 8 | L26: 8 | M26: 8 | N26: 8 | O26: 8 | P26: 8 | R26: 8 | S26: 8 | T26: 8 | U26: 8 | V26: 8 | W26: 8 | Y26: 8 | Z26: 8 | AA26: 8 | AB26: 8 | AC26: 8 | AD26: 8 | AJ26: =SUM(D26:AI26) -> 190
C27: 연장 | F27: 2 | G27: 2 | H27: 2 | L27: 2 | M27: 2 | O27: 2 | AD27: 2 | AJ27: =SUM(D27:AI27) -> 14
C28: 주특 | J28: 8 | Q28: 8 | X28: 8 | AE28: 8 | AJ28: =SUM(D28:AI28) -> 32
C29: 특잔 | AJ29: =SUM(D29:AI29) -> 0
C30: 심야 | AJ30: =SUM(D30:AI30) -> 0
C31: 근태 | T31: 설날 | AJ31: 계

Sheet 장희숙
B1: 어브코스
B3: 급 여 | N3: 세 액 및 공 제
B4: 기 본 급 | H4: =AJ26 -> 192 | K4: =H4*10320 -> 1981440 | N4: 갑 근 세
B5: 잔업수당 | H5: =AJ27 -> 4 | K5: =H5*10320*1.5 -> 61920 | N5: 소 득 세 | T5: =H17*3.3% -> 79823.04
B6: 휴일수당 | K6: =H6*10320*1.5 -> 0 | N6: 건 강 보 험
B7: 특근수당 | H7: =AJ28 -> 24 | K7: =H7*10320*1.5 -> 371520 | N7: 장기요양
B8: 심야수당 | H8: =AJ29 -> 0 | K8: =ROUNDDOWN(H8*10320*0.5,-1) -> 0 | N8: 국 민 연 금
B9: 지각/조퇴 | N9: 공과금
B10: 부서수당 | N10: 가 불 금
B11: 만근수당 | N11: 선지급
B12: 상여금
B13: 간식대 | H13: 4000
N16: 공 제 총 액 | T16: =SUM(T4:Y11) -> 79823.04
B17: 급 여 총 액 | H17: =SUM(K4,K5,K6,K7,K8,K9,H10,H11,H12,H13,H14,H15,H16) -> 2418880 | N17: 실 수 령 액 | T17: =H17-T16 -> 2339057
N19: 한 달 동안 수고 많으셨습니다 ^^
P21: 이름 : | T21: 장희숙
B24: 이름 | C24: 구분 | D24: 1 | E24: 2 | F24: 3 | G24: 4 | H24: 5 | I24: 6 | J24: 7 | K24: 8 | L24: 9 | M24: 10 | N24: 11 | O24: 12 | P24: 13 | Q24: 14 | R24: 15 | S24: 16 | T24: 17 | U24: 18 | V24: 19 | W24: 20 | X24: 21 | Y24: 22 | Z24: 23 | AA24: 24 | AB24: 25 | AC24: 26 | AD24: 27 | AE24: 28 | AI24: 소급 | AJ24: 합계
D25: 일 | E25: 월 | F25: 화 | G25: 수 | H25: 목 | I25: 금 | J25: 토 | K25: 일 | L25: 월 | M25: 화 | N25: 수 | O25: 목 | P25: 금 | Q25: 토 | R25: 일 | S25: 월 | T25: 화 | U25: 수 | V25: 목 | W25: 금 | X25: 토 | Y25: 일 | Z25: 월 | AA25: 화 | AB25: 수 | AC25: 목 | AD25: 금 | AE25: 토
B26: =T21 -> 장희숙 | C26: 기본 | D26: 8 | E26: 8 | F26: 8 | G26: 8 | H26: 8 | I26: 8 | K26: 8 | L26: 8 | M26: 8 | N26: 8 | O26: 8 | P26: 8 | R26: 8 | S26: 8 | T26: 8 | U26: 8 | V26: 8 | W26: 8 | Y26: 8 | Z26: 8 | AA26: 8 | AB26: 8 | AC26: 8 | AD26: 8 | AJ26: =SUM(D26:AI26) -> 192
C27: 연장 | E27: 2 | L27: 2 | AJ27: =SUM(D27:AI27) -> 4
C28: 주특 | J28: 8 | Q28: 8 | AE28: 8 | AJ28: =SUM(D28:AI28) -> 24
C29: 특잔 | AJ29: =SUM(D29:AI29) -> 0
C30: 심야 | AJ30: =SUM(D30:AI30) -> 0
C31: 근태 | T31: 설날 | AJ31: 계

Sheet 김수정B
B1: 어브코스
B3: 급 여 | N3: 세 액 및 공 제
B4: 기 본 급 | H4: =AJ26 -> 192 | K4: =H4*10320 -> 1981440 | N4: 갑 근 세
B5: 잔업수당 | H5: =AJ27 -> 16 | K5: =H5*10320*1.5 -> 247680 | N5: 소 득 세 | T5: =H17*3.3% -> 78175.68
B6: 휴일수당 | K6: =H6*10320*1.5 -> 0 | N6: 건 강 보 험
B7: 특근수당 | H7: =AJ28 -> 8 | K7: =H7*10320*1.5 -> 123840 | N7: 장기요양
B8: 심야수당 | H8: =AJ29 -> 0 | K8: =ROUNDDOWN(H8*10320*0.5,-1) -> 0 | N8: 국 민 연 금
B9: 지각/조퇴 | N9: 공과금
B10: 부서수당 | N10: 가 불 금
B11: 만근수당 | N11: 선지급
B12: 상여금
B13: 간식대 | H13: 16000
N16: 공 제 총 액 | T16: =SUM(T4:Y11) -> 78175.68
B17: 급 여 총 액 | H17: =SUM(K4,K5,K6,K7,K8,K9,H10,H11,H12,H13,H14,H15,H16) -> 2368960 | N17: 실 수 령 액 | T17: =H17-T16 -> 2290784.3
N19: 한 달 동안 수고 많으셨습니다 ^^
P21: 이름 : | T21: 김수정
B24: 이름 | C24: 구분 | D24: 1 | E24: 2 | F24: 3 | G24: 4 | H24: 5 | I24: 6 | J24: 7 | K24: 8 | L24: 9 | M24: 10 | N24: 11 | O24: 12 | P24: 13 | Q24: 14 | R24: 15 | S24: 16 | T24: 17 | U24: 18 | V24: 19 | W24: 20 | X24: 21 | Y24: 22 | Z24: 23 | AA24: 24 | AB24: 25 | AC24: 26 | AD24: 27 | AE24: 28 | AI24: 소급 | AJ24: 합계
D25: 일 | E25: 월 | F25: 화 | G25: 수 | H25: 목 | I25: 금 | J25: 토 | K25: 일 | L25: 월 | M25: 화 | N25: 수 | O25: 목 | P25: 금 | Q25: 토 | R25: 일 | S25: 월 | T25: 화 | U25: 수 | V25: 목 | W25: 금 | X25: 토 | Y25: 일 | Z25: 월 | AA25: 화 | AB25: 수 | AC25: 목 | AD25: 금 | AE25: 토
B26: =T21 -> 김수정 | C26: 기본 | D26: 8 | E26: 8 | F26: 8 | G26: 8 | H26: 8 | I26: 8 | K26: 8 | L26: 8 | M26: 8 | N26: 8 | O26: 8 | P26: 8 | R26: 8 | S26: 8 | T26: 8 | U26: 8 | V26: 8 | W26: 8 | Y26: 8 | Z26: 8 | AA26: 8 | AB26: 8 | AC26: 8 | AD26: 8 | AJ26: =SUM(D26:AI26) -> 192
C27: 연장 | E27: 2 | F27: 2 | G27: 2 | H27: 2 | L27: 2 | M27: 2 | O27: 2 | AD27: 2 | AJ27: =SUM(D27:AI27) -> 16
C28: 주특 | AE28: 8 | AJ28: =SUM(D28:AI28) -> 8
C29: 특잔 | AJ29: =SUM(D29:AI29) -> 0
C30: 심야 | AJ30: =SUM(D30:AI30) -> 0
C31: 근태 | T31: 설날 | AJ31: 계

Sheet 박서원B
B1: 어브코스
B3: 급 여 | N3: 세 액 및 공 제
B4: 기 본 급 | H4: =AJ26 -> 182 | K4: =H4*10320 -> 1878240 | N4: 갑 근 세
B5: 잔업수당 | H5: =AJ27 -> 15 | K5: =H5*10320*1.5 -> 232200 | N5: 소 득 세 | T5: =H17*3.3% -> 86453.4
B6: 휴일수당 | K6: =H6*10320*1.5 -> 0 | N6: 건 강 보 험
B7: 특근수당 | H7: =AJ28 -> 32 | K7: =H7*10320*1.5 -> 495360 | N7: 장기요양
B8: 심야수당 | H8: =AJ29 -> 0 | K8: =ROUNDDOWN(H8*10320*0.5,-1) -> 0 | N8: 국 민 연 금
B9: 지각/조퇴 | N9: 공과금
B10: 부서수당 | N10: 가 불 금
B11: 만근수당 | N11: 선지급
B12: 상여금
B13: 간식대 | H13: 14000
N16: 공 제 총 액 | T16: =SUM(T4:Y11) -> 86453.4
B17: 급 여 총 액 | H17: =SUM(K4,K5,K6,K7,K8,K9,H10,H11,H12,H13,H14,H15,H16) -> 2619800 | N17: 실 수 령 액 | T17: =H17-T16 -> 2533346.6
N19: 한 달 동안 수고 많으셨습니다 ^^
P21: 이름 : | T21: 박서원
B24: 이름 | C24: 구분 | D24: 1 | E24: 2 | F24: 3 | G24: 4 | H24: 5 | I24: 6 | J24: 7 | K24: 8 | L24: 9 | M24: 10 | N24: 11 | O24: 12 | P24: 13 | Q24: 14 | R24: 15 | S24: 16 | T24: 17 | U24: 18 | V24: 19 | W24: 20 | X24: 21 | Y24: 22 | Z24: 23 | AA24: 24 | AB24: 25 | AC24: 26 | AD24: 27 | AE24: 28 | AI24: 소급 | AJ24: 합계
D25: 일 | E25: 월 | F25: 화 | G25: 수 | H25: 목 | I25: 금 | J25: 토 | K25: 일 | L25: 월 | M25: 화 | N25: 수 | O25: 목 | P25: 금 | Q25: 토 | R25: 일 | S25: 월 | T25: 화 | U25: 수 | V25: 목 | W25: 금 | X25: 토 | Y25: 일 | Z25: 월 | AA25: 화 | AB25: 수 | AC25: 목 | AD25: 금 | AE25: 토
B26: =T21 -> 박서원 | C26: 기본 | D26: 8 | E26: 6 | F26: 8 | G26: 8 | H26: 8 | I26: 8 | K26: 8 | L26: 8 | M26: 8 | N26: 8 | O26: 8 | P26: 8 | R26: 8 | S26: 8 | T26: 8 | U26: 8 | V26: 8 | W26: 8 | Y26: 8 | Z26: 8 | AA26: 8 | AB26: 8 | AD26: 8 | AJ26: =SUM(D26:AI26) -> 182
C27: 연장 | F27: 2 | G27: 2 | H27: 2 | L27: 2 | M27: 2 | O27: 2 | V27: 1 | AD27: 2 | AJ27: =SUM(D27:AI27) -> 15
C28: 주특 | J28: 8 | Q28: 8 | X28: 8 | AE28: 8 | AJ28: =SUM(D28:AI28) -> 32
C29: 특잔 | AJ29: =SUM(D29:AI29) -> 0
C30: 심야 | AJ30: =SUM(D30:AI30) -> 0
C31: 근태 | T31: 설날 | AC31: 결근 | AJ31: 계

Sheet 최삼순
B1: 어브코스
B3: 급 여 | N3: 세 액 및 공 제
B4: 기 본 급 | H4: =AJ26 -> 183 | K4: =H4*10320 -> 1888560 | N4: 갑 근 세
B5: 잔업수당 | H5: =AJ27 -> 12 | K5: =H5*10320*1.5 -> 185760 | N5: 소 득 세 | T5: =H17*3.3% -> 85195.44
B6: 휴일수당 | K6: =H6*10320*1.5 -> 0 | N6: 건 강 보 험
B7: 특근수당 | H7: =AJ28 -> 32 | K7: =H7*10320*1.5 -> 495360 | N7: 장기요양
B8: 심야수당 | H8: =AJ29 -> 0 | K8: =ROUNDDOWN(H8*10320*0.5,-1) -> 0 | N8: 국 민 연 금
B9: 지각/조퇴 | N9: 공과금
B10: 부서수당 | N10: 가 불 금
B11: 만근수당 | N11: 선지급
B12: 상여금
B13: 간식대 | H13: 12000
N16: 공 제 총 액 | T16: =SUM(T4:Y11) -> 85195.44
B17: 급 여 총 액 | H17: =SUM(K4,K5,K6,K7,K8,K9,H10,H11,H12,H13,H14,H15,H16) -> 2581680 | N17: 실 수 령 액 | T17: =H17-T16 -> 2496484.6
N19: 한 달 동안 수고 많으셨습니다 ^^
P21: 이름 : | T21: 최삼순
B24: 이름 | C24: 구분 | D24: 1 | E24: 2 | F24: 3 | G24: 4 | H24: 5 | I24: 6 | J24: 7 | K24: 8 | L24: 9 | M24: 10 | N24: 11 | O24: 12 | P24: 13 | Q24: 14 | R24: 15 | S24: 16 | T24: 17 | U24: 18 | V24: 19 | W24: 20 | X24: 21 | Y24: 22 | Z24: 23 | AA24: 24 | AB24: 25 | AC24: 26 | AD24: 27 | AE24: 28 | AI24: 소급 | AJ24: 합계
D25: 일 | E25: 월 | F25: 화 | G25: 수 | H25: 목 | I25: 금 | J25: 토 | K25: 일 | L25: 월 | M25: 화 | N25: 수 | O25: 목 | P25: 금 | Q25: 토 | R25: 일 | S25: 월 | T25: 화 | U25: 수 | V25: 목 | W25: 금 | X25: 토 | Y25: 일 | Z25: 월 | AA25: 화 | AB25: 수 | AC25: 목 | AD25: 금 | AE25: 토
B26: =T21 -> 최삼순 | C26: 기본 | D26: 8 | E26: 6 | F26: 8 | G26: 8 | H26: 8 | I26: 4 | K26: 8 | L26: 8 | M26: 8 | N26: 5 | O26: 8 | P26: 8 | R26: 8 | S26: 8 | T26: 8 | U26: 8 | V26: 8 | W26: 8 | Y26: 8 | Z26: 8 | AA26: 8 | AB26: 8 | AC26: 8 | AD26: 8 | AJ26: =SUM(D26:AI26) -> 183
C27: 연장 | F27: 2 | G27: 2 | H27: 2 | L27: 2 | M27: 2 | O27: 2 | AJ27: =SUM(D27:AI27) -> 12
C28: 주특 | J28: 8 | Q28: 8 | X28: 8 | AE28: 8 | AJ28: =SUM(D28:AI28) -> 32
C29: 특잔 | AJ29: =SUM(D29:AI29) -> 0
C30: 심야 | AJ30: =SUM(D30:AI30) -> 0
C31: 근태 | I31: 조퇴 | N31: 지각 | T31: 설날 | AJ31: 계

Sheet 프라타레네린
B1: 어브코스
B3: 급 여 | N3: 세 액 및 공 제
B4: 기 본 급 | H4: =AJ26 -> 190 | K4: =H4*10320 -> 1960800 | N4: 갑 근 세
B5: 잔업수당 | H5: =AJ27 -> 12 | K5: =H5*10320*1.5 -> 185760 | N5: 소 득 세 | T5: =H17*3.3% -> 71232.48
B6: 휴일수당 | K6: =H6*10320*1.5 -> 0 | N6: 건 강 보 험
B7: 특근수당 | H7: =AJ28 -> 0 | K7: =H7*10320*1.5 -> 0 | N7: 장기요양
B8: 심야수당 | H8: =AJ29 -> 0 | K8: =ROUNDDOWN(H8*10320*0.5,-1) -> 0 | N8: 국 민 연 금
B9: 지각/조퇴 | N9: 공과금
B10: 부서수당 | N10: 가 불 금
B11: 만근수당 | N11: 선지급
B12: 상여금
B13: 간식대 | H13: 12000
N16: 공 제 총 액 | T16: =SUM(T4:Y11) -> 71232.48
B17: 급 여 총 액 | H17: =SUM(K4,K5,K6,K7,K8,K9,H10,H11,H12,H13,H14,H15,H16) -> 2158560 | N17: 실 수 령 액 | T17: =H17-T16 -> 2087327.5
N19: 한 달 동안 수고 많으셨습니다 ^^
P21: 이름 : | T21: 프라타레네린
B24: 이름 | C24: 구분 | D24: 1 | E24: 2 | F24: 3 | G24: 4 | H24: 5 | I24: 6 | J24: 7 | K24: 8 | L24: 9 | M24: 10 | N24: 11 | O24: 12 | P24: 13 | Q24: 14 | R24: 15 | S24: 16 | T24: 17 | U24: 18 | V24: 19 | W24: 20 | X24: 21 | Y24: 22 | Z24: 23 | AA24: 24 | AB24: 25 | AC24: 26 | AD24: 27 | AE24: 28 | AI24: 소급 | AJ24: 합계
D25: 일 | E25: 월 | F25: 화 | G25: 수 | H25: 목 | I25: 금 | J25: 토 | K25: 일 | L25: 월 | M25: 화 | N25: 수 | O25: 목 | P25: 금 | Q25: 토 | R25: 일 | S25: 월 | T25: 화 | U25: 수 | V25: 목 | W25: 금 | X25: 토 | Y25: 일 | Z25: 월 | AA25: 화 | AB25: 수 | AC25: 목 | AD25: 금 | AE25: 토
B26: =T21 -> 프라타레네린 | C26: 기본 | D26: 8 | E26: 6 | F26: 8 | G26: 8 | H26: 8 | I26: 8 | K26: 8 | L26: 8 | M26: 8 | N26: 8 | O26: 8 | P26: 8 | R26: 8 | S26: 8 | T26: 8 | U26: 8 | V26: 8 | W26: 8 | Y26: 8 | Z26: 8 | AA26: 8 | AB26: 8 | AC26: 8 | AD26: 8 | AJ26: =SUM(D26:AI26) -> 190
C27: 연장 | F27: 2 | G27: 2 | H27: 2 | L27: 2 | O27: 2 | AD27: 2 | AJ27: =SUM(D27:AI27) -> 12
C28: 주특 | AJ28: =SUM(D28:AI28) -> 0
C29: 특잔 | AJ29: =SUM(D29:AI29) -> 0
C30: 심야 | AJ30: =SUM(D30:AI30) -> 0
C31: 근태 | T31: 설날 | AJ31: 계

Sheet 육은심
B1: 어브코스
B3: 급 여 | N3: 세 액 및 공 제
B4: 기 본 급 | H4: =AJ26 -> 190 | K4: =H4*10320 -> 1960800 | N4: 갑 근 세
B5: 잔업수당 | H5: =AJ27 -> 12 | K5: =H5*10320*1.5 -> 185760 | N5: 소 득 세 | T5: =H17*3.3% -> 83492.64
B6: 휴일수당 | K6: =H6*10320*1.5 -> 0 | N6: 건 강 보 험
B7: 특근수당 | H7: =AJ28 -> 24 | K7: =H7*10320*1.5 -> 371520 | N7: 장기요양
B8: 심야수당 | H8: =AJ29 -> 0 | K8: =ROUNDDOWN(H8*10320*0.5,-1) -> 0 | N8: 국 민 연 금
B9: 지각/조퇴 | N9: 공과금
B10: 부서수당 | N10: 가 불 금
B11: 만근수당 | N11: 선지급
B12: 상여금
B13: 간식대 | H13: 12000
N16: 공 제 총 액 | T16: =SUM(T4:Y11) -> 83492.64
B17: 급 여 총 액 | H17: =SUM(K4,K5,K6,K7,K8,K9,H10,H11,H12,H13,H14,H15,H16) -> 2530080 | N17: 실 수 령 액 | T17: =H17-T16 -> 2446587.4
N19: 한 달 동안 수고 많으셨습니다 ^^
P21: 이름 : | T21: 육은심
B24: 이름 | C24: 구분 | D24: 1 | E24: 2 | F24: 3 | G24: 4 | H24: 5 | I24: 6 | J24: 7 | K24: 8 | L24: 9 | M24: 10 | N24: 11 | O24: 12 | P24: 13 | Q24: 14 | R24: 15 | S24: 16 | T24: 17 | U24: 18 | V24: 19 | W24: 20 | X24: 21 | Y24: 22 | Z24: 23 | AA24: 24 | AB24: 25 | AC24: 26 | AD24: 27 | AE24: 28 | AI24: 소급 | AJ24: 합계
D25: 일 | E25: 월 | F25: 화 | G25: 수 | H25: 목 | I25: 금 | J25: 토 | K25: 일 | L25: 월 | M25: 화 | N25: 수 | O25: 목 | P25: 금 | Q25: 토 | R25: 일 | S25: 월 | T25: 화 | U25: 수 | V25: 목 | W25: 금 | X25: 토 | Y25: 일 | Z25: 월 | AA25: 화 | AB25: 수 | AC25: 목 | AD25: 금 | AE25: 토
B26: =T21 -> 육은심 | C26: 기본 | D26: 8 | E26: 6 | F26: 8 | G26: 8 | H26: 8 | I26: 8 | K26: 8 | L26: 8 | M26: 8 | N26: 8 | O26: 8 | P26: 8 | R26: 8 | S26: 8 | T26: 8 | U26: 8 | V26: 8 | W26: 8 | Y26: 8 | Z26: 8 | AA26: 8 | AB26: 8 | AC26: 8 | AD26: 8 | AJ26: =SUM(D26:AI26) -> 190
C27: 연장 | F27: 2 | G27: 2 | H27: 2 | L27: 2 | M27: 2 | O27: 2 | AJ27: =SUM(D27:AI27) -> 12
C28: 주특 | J28: 8 | Q28: 8 | X28: 8 | AJ28: =SUM(D28:AI28) -> 24
C29: 특잔 | AJ29: =SUM(D29:AI29) -> 0
C30: 심야 | AJ30: =SUM(D30:AI30) -> 0
C31: 근태 | P31: 반차 | T31: 설날 | AJ31: 계

Sheet 김수현
B1: 어브코스
B3: 급 여 | N3: 세 액 및 공 제
B4: 기 본 급 | H4: =AJ26 -> 190 | K4: =H4*10320 -> 1960800 | N4: 갑 근 세
B5: 잔업수당 | H5: =AJ27 -> 10 | K5: =H5*10320*1.5 -> 154800 | N5: 소 득 세 | T5: =H17*3.3% -> 70144.8
B6: 휴일수당 | K6: =H6*10320*1.5 -> 0 | N6: 건 강 보 험
B7: 특근수당 | H7: =AJ28 -> 0 | K7: =H7*10320*1.5 -> 0 | N7: 장기요양
B8: 심야수당 | H8: =AJ29 -> 0 | K8: =ROUNDDOWN(H8*10320*0.5,-1) -> 0 | N8: 국 민 연 금
B9: 지각/조퇴 | N9: 공과금
B10: 부서수당 | N10: 가 불 금
B11: 만근수당 | N11: 선지급
B12: 상여금
B13: 간식대 | H13: 10000
N16: 공 제 총 액 | T16: =SUM(T4:Y11) -> 70144.8
B17: 급 여 총 액 | H17: =SUM(K4,K5,K6,K7,K8,K9,H10,H11,H12,H13,H14,H15,H16) -> 2125600 | N17: 실 수 령 액 | T17: =H17-T16 -> 2055455.2
N19: 한 달 동안 수고 많으셨습니다 ^^
P21: 이름 : | T21: 김수현
B24: 이름 | C24: 구분 | D24: 1 | E24: 2 | F24: 3 | G24: 4 | H24: 5 | I24: 6 | J24: 7 | K24: 8 | L24: 9 | M24: 10 | N24: 11 | O24: 12 | P24: 13 | Q24: 14 | R24: 15 | S24: 16 | T24: 17 | U24: 18 | V24: 19 | W24: 20 | X24: 21 | Y24: 22 | Z24: 23 | AA24: 24 | AB24: 25 | AC24: 26 | AD24: 27 | AE24: 28 | AI24: 소급 | AJ24: 합계
D25: 일 | E25: 월 | F25: 화 | G25: 수 | H25: 목 | I25: 금 | J25: 토 | K25: 일 | L25: 월 | M25: 화 | N25: 수 | O25: 목 | P25: 금 | Q25: 토 | R25: 일 | S25: 월 | T25: 화 | U25: 수 | V25: 목 | W25: 금 | X25: 토 | Y25: 일 | Z25: 월 | AA25: 화 | AB25: 수 | AC25: 목 | AD25: 금 | AE25: 토
B26: =T21 -> 김수현 | C26: 기본 | D26: 8 | E26: 6 | F26: 8 | G26: 8 | H26: 8 | I26: 8 | K26: 8 | L26: 8 | M26: 8 | N26: 8 | O26: 8 | P26: 8 | R26: 8 | S26: 8 | T26: 8 | U26: 8 | V26: 8 | W26: 8 | Y26: 8 | Z26: 8 | AA26: 8 | AB26: 8 | AC26: 8 | AD26: 8 | AJ26: =SUM(D26:AI26) -> 190
C27: 연장 | F27: 2 | H27: 2 | L27: 2 | M27: 2 | O27: 2 | AJ27: =SUM(D27:AI27) -> 10
C28: 주특 | AJ28: =SUM(D28:AI28) -> 0
C29: 특잔 | AJ29: =SUM(D29:AI29) -> 0
C30: 심야 | AJ30: =SUM(D30:AI30) -> 0
C31: 근태 | T31: 설날 | AJ31: 계

Sheet 한계숙
B1: 어브코스
B3: 급 여 | N3: 세 액 및 공 제
B4: 기 본 급 | H4: =AJ26 -> 192 | K4: =H4*10320 -> 1981440 | N4: 갑 근 세
B5: 잔업수당 | H5: =AJ27 -> 16 | K5: =H5*10320*1.5 -> 247680 | N5: 소 득 세 | T5: =H17*3.3% -> 93160.32
B6: 휴일수당 | K6: =H6*10320*1.5 -> 0 | N6: 건 강 보 험
B7: 특근수당 | H7: =AJ28 -> 32 | K7: =H7*10320*1.5 -> 495360 | N7: 장기요양
B8: 심야수당 | H8: =AJ29 -> 0 | K8: =ROUNDDOWN(H8*10320*0.5,-1) -> 0 | N8: 국 민 연 금
B9: 지각/조퇴 | N9: 공과금
B10: 부서수당 | N10: 가 불 금
B11: 만근수당 | N11: 선지급 | T11: 2729880
B12: 상여금 | H12: 82560
B13: 간식대 | H13: 16000
N16: 공 제 총 액 | T16: =SUM(T4:Y11) -> 2823040.3
B17: 급 여 총 액 | H17: =SUM(K4,K5,K6,K7,K8,K9,H10,H11,H12,H13,H14,H15,H16) -> 2823040 | N17: 실 수 령 액 | T17: =H17-T16 -> -0.32
N19: 한 달 동안 수고 많으셨습니다 ^^
P21: 이름 : | T21: 한계숙
B24: 이름 | C24: 구분 | D24: 1 | E24: 2 | F24: 3 | G24: 4 | H24: 5 | I24: 6 | J24: 7 | K24: 8 | L24: 9 | M24: 10 | N24: 11 | O24: 12 | P24: 13 | Q24: 14 | R24: 15 | S24: 16 | T24: 17 | U24: 18 | V24: 19 | W24: 20 | X24: 21 | Y24: 22 | Z24: 23 | AA24: 24 | AB24: 25 | AC24: 26 | AD24: 27 | AE24: 28 | AI24: 소급 | AJ24: 합계
D25: 일 | E25: 월 | F25: 화 | G25: 수 | H25: 목 | I25: 금 | J25: 토 | K25: 일 | L25: 월 | M25: 화 | N25: 수 | O25: 목 | P25: 금 | Q25: 토 | R25: 일 | S25: 월 | T25: 화 | U25: 수 | V25: 목 | W25: 금 | X25: 토 | Y25: 일 | Z25: 월 | AA25: 화 | AB25: 수 | AC25: 목 | AD25: 금 | AE25: 토
B26: =T21 -> 한계숙 | C26: 기본 | D26: 8 | E26: 8 | F26: 8 | G26: 8 | H26: 8 | I26: 8 | K26: 8 | L26: 8 | M26: 8 | N26: 8 | O26: 8 | P26: 8 | R26: 8 | S26: 8 | T26: 8 | U26: 8 | V26: 8 | W26: 8 | Y26: 8 | Z26: 8 | AA26: 8 | AB26: 8 | AC26: 8 | AD26: 8 | AJ26: =SUM(D26:AI26) -> 192
C27: 연장 | E27: 2 | F27: 2 | G27: 2 | H27: 2 | L27: 2 | M27: 2 | O27: 2 | AD27: 2 | AJ27: =SUM(D27:AI27) -> 16
C28: 주특 | J28: 8 | Q28: 8 | X28: 8 | AE28: 8 | AJ28: =SUM(D28:AI28) -> 32
C29: 특잔 | AJ29: =SUM(D29:AI29) -> 0
C30: 심야 | AJ30: =SUM(D30:AI30) -> 0
C31: 근태 | T31: 설날 | AJ31: 계

Sheet 풍춘향
B1: 어브코스
B3: 급 여 | N3: 세 액 및 공 제
B4: 기 본 급 | H4: =AJ26 -> 190 | K4: =H4*10320 -> 1960800 | N4: 갑 근 세
B5: 잔업수당 | H5: =AJ27 -> 12 | K5: =H5*10320*1.5 -> 185760 | N5: 소 득 세 | T5: =H17*3.3% -> 87579.36
B6: 휴일수당 | K6: =H6*10320*1.5 -> 0 | N6: 건 강 보 험
B7: 특근수당 | H7: =AJ28 -> 32 | K7: =H7*10320*1.5 -> 495360 | N7: 장기요양
B8: 심야수당 | H8: =AJ29 -> 0 | K8: =ROUNDDOWN(H8*10320*0.5,-1) -> 0 | N8: 국 민 연 금
B9: 지각/조퇴 | N9: 공과금
B10: 부서수당 | N10: 가 불 금
B11: 만근수당 | N11: 선지급
B12: 상여금
B13: 간식대 | H13: 12000
N16: 공 제 총 액 | T16: =SUM(T4:Y11) -> 87579.36
B17: 급 여 총 액 | H17: =SUM(K4,K5,K6,K7,K8,K9,H10,H11,H12,H13,H14,H15,H16) -> 2653920 | N17: 실 수 령 액 | T17: =H17-T16 -> 2566340.6
N19: 한 달 동안 수고 많으셨습니다 ^^
P21: 이름 : | T21: 풍춘향
B24: 이름 | C24: 구분 | D24: 1 | E24: 2 | F24: 3 | G24: 4 | H24: 5 | I24: 6 | J24: 7 | K24: 8 | L24: 9 | M24: 10 | N24: 11 | O24: 12 | P24: 13 | Q24: 14 | R24: 15 | S24: 16 | T24: 17 | U24: 18 | V24: 19 | W24: 20 | X24: 21 | Y24: 22 | Z24: 23 | AA24: 24 | AB24: 25 | AC24: 26 | AD24: 27 | AE24: 28 | AI24: 소급 | AJ24: 합계
D25: 일 | E25: 월 | F25: 화 | G25: 수 | H25: 목 | I25: 금 | J25: 토 | K25: 일 | L25: 월 | M25: 화 | N25: 수 | O25: 목 | P25: 금 | Q25: 토 | R25: 일 | S25: 월 | T25: 화 | U25: 수 | V25: 목 | W25: 금 | X25: 토 | Y25: 일 | Z25: 월 | AA25: 화 | AB25: 수 | AC25: 목 | AD25: 금 | AE25: 토
B26: =T21 -> 풍춘향 | C26: 기본 | D26: 8 | E26: 6 | F26: 8 | G26: 8 | H26: 8 | I26: 8 | K26: 8 | L26: 8 | M26: 8 | N26: 8 | O26: 8 | P26: 8 | R26: 8 | S26: 8 | T26: 8 | U26: 8 | V26: 8 | W26: 8 | Y26: 8 | Z26: 8 | AA26: 8 | AB26: 8 | AC26: 8 | AD26: 8 | AJ26: =SUM(D26:AI26) -> 190
C27: 연장 | F27: 2 | G27: 2 | H27: 2 | L27: 2 | M27: 2 | O27: 2 | AJ27: =SUM(D27:AI27) -> 12
C28: 주특 | J28: 8 | Q28: 8 | X28: 8 | AE28: 8 | AJ28: =SUM(D28:AI28) -> 32
C29: 특잔 | AJ29: =SUM(D29:AI29) -> 0
C30: 심야 | AJ30: =SUM(D30:AI30) -> 0
C31: 근태 | T31: 설날 | AJ31: 계

Sheet 유지원
B1: 어브코스
B3: 급 여 | N3: 세 액 및 공 제
B4: 기 본 급 | H4: =AJ26 -> 0 | K4: =H4*10320 -> 0 | N4: 갑 근 세
B5: 잔업수당 | H5: =AJ27 -> 0 | K5: =H5*10320*1.5 -> 0 | N5: 소 득 세
B6: 휴일수당 | K6: =H6*10320*1.5 -> 0 | N6: 건 강 보 험
B7: 특근수당 | H7: =AJ28 -> 0 | K7: =H7*10320*1.5 -> 0 | N7: 장기요양
B8: 심야수당 | H8: =AJ29 -> 0 | K8: =ROUNDDOWN(H8*10320*0.5,-1) -> 0 | N8: 국 민 연 금
B9: 지각/조퇴 | N9: 고용보험 | T9: =ROUNDDOWN(H17*0.9%,-1) -> 4950
B10: 부서수당 | N10: 가 불 금
B11: 만근수당 | N11: 선지급 | T11: 545050
B12: 상여금
B13: 간식대
N16: 공 제 총 액 | T16: =SUM(T4:Y11) -> 550000
B17: 급 여 총 액 | H17: 550000 | N17: 실 수 령 액 | T17: =H17-T16 -> 0
N19: 한 달 동안 수고 많으셨습니다 ^^
P21: 이름 : | T21: 유지원
B24: 이름 | C24: 구분 | D24: 1 | E24: 2 | F24: 3 | G24: 4 | H24: 5 | I24: 6 | J24: 7 | K24: 8 | L24: 9 | M24: 10 | N24: 11 | O24: 12 | P24: 13 | Q24: 14 | R24: 15 | S24: 16 | T24: 17 | U24: 18 | V24: 19 | W24: 20 | X24: 21 | Y24: 22 | Z24: 23 | AA24: 24 | AB24: 25 | AC24: 26 | AD24: 27 | AE24: 28 | AI24: 소급 | AJ24: 합계
D25: 일 | E25: 월 | F25: 화 | G25: 수 | H25: 목 | I25: 금 | J25: 토 | K25: 일 | L25: 월 | M25: 화 | N25: 수 | O25: 목 | P25: 금 | Q25: 토 | R25: 일 | S25: 월 | T25: 화 | U25: 수 | V25: 목 | W25: 금 | X25: 토 | Y25: 일 | Z25: 월 | AA25: 화 | AB25: 수 | AC25: 목 | AD25: 금 | AE25: 토
B26: =T21 -> 유지원 | C26: 기본 | AJ26: =SUM(D26:AI26) -> 0
C27: 연장 | AJ27: =SUM(D27:AI27) -> 0
C28: 주특 | AJ28: =SUM(D28:AI28) -> 0
C29: 특잔 | AJ29: =SUM(D29:AI29) -> 0
C30: 심야 | AJ30: =SUM(D30:AI30) -> 0
C31: 근태 | AJ31: 계

Sheet 김연순
B1: 어브코스
B3: 급 여 | N3: 세 액 및 공 제
B4: 기 본 급 | H4: =AJ26 -> 190 | K4: =H4*10320 -> 1960800 | N4: 갑 근 세
B5: 잔업수당 | H5: =AJ27 -> 12 | K5: =H5*10320*1.5 -> 185760 | N5: 소 득 세 | T5: =H17*3.3% -> 83492.64
B6: 휴일수당 | K6: =H6*10320*1.5 -> 0 | N6: 건 강 보 험
B7: 특근수당 | H7: =AJ28 -> 24 | K7: =H7*10320*1.5 -> 371520 | N7: 장기요양
B8: 심야수당 | H8: =AJ29 -> 0 | K8: =ROUNDDOWN(H8*10320*0.5,-1) -> 0 | N8: 국 민 연 금
B9: 지각/조퇴 | N9: 공과금
B10: 부서수당 | N10: 가 불 금
B11: 만근수당 | N11: 선지급
B12: 상여금
B13: 간식대 | H13: 12000
N16: 공 제 총 액 | T16: =SUM(T4:Y11) -> 83492.64
B17: 급 여 총 액 | H17: =SUM(K4,K5,K6,K7,K8,K9,H10,H11,H12,H13,H14,H15,H16) -> 2530080 | N17: 실 수 령 액 | T17: =H17-T16 -> 2446587.4
N19: 한 달 동안 수고 많으셨습니다 ^^
P21: 이름 : | T21: 김연순
B24: 이름 | C24: 구분 | D24: 1 | E24: 2 | F24: 3 | G24: 4 | H24: 5 | I24: 6 | J24: 7 | K24: 8 | L24: 9 | M24: 10 | N24: 11 | O24: 12 | P24: 13 | Q24: 14 | R24: 15 | S24: 16 | T24: 17 | U24: 18 | V24: 19 | W24: 20 | X24: 21 | Y24: 22 | Z24: 23 | AA24: 24 | AB24: 25 | AC24: 26 | AD24: 27 | AE24: 28 | AI24: 소급 | AJ24: 합계
D25: 일 | E25: 월 | F25: 화 | G25: 수 | H25: 목 | I25: 금 | J25: 토 | K25: 일 | L25: 월 | M25: 화 | N25: 수 | O25: 목 | P25: 금 | Q25: 토 | R25: 일 | S25: 월 | T25: 화 | U25: 수 | V25: 목 | W25: 금 | X25: 토 | Y25: 일 | Z25: 월 | AA25: 화 | AB25: 수 | AC25: 목 | AD25: 금 | AE25: 토
B26: =T21 -> 김연순 | C26: 기본 | D26: 8 | E26: 6 | F26: 8 | G26: 8 | H26: 8 | I26: 8 | K26: 8 | L26: 8 | M26: 8 | N26: 8 | O26: 8 | P26: 8 | R26: 8 | S26: 8 | T26: 8 | U26: 8 | V26: 8 | W26: 8 | Y26: 8 | Z26: 8 | AA26: 8 | AB26: 8 | AC26: 8 | AD26: 8 | AJ26: =SUM(D26:AI26) -> 190
C27: 연장 | F27: 2 | G27: 2 | H27: 2 | L27: 2 | M27: 2 | O27: 2 | AJ27: =SUM(D27:AI27) -> 12
C28: 주특 | J28: 8 | Q28: 8 | X28: 8 | AJ28: =SUM(D28:AI28) -> 24
C29: 특잔 | AJ29: =SUM(D29:AI29) -> 0
C30: 심야 | AJ30: =SUM(D30:AI30) -> 0
C31: 근태 | T31: 설날 | AJ31: 계

Sheet 지미경
B1: 어브코스
B3: 급 여 | N3: 세 액 및 공 제
B4: 기 본 급 | H4: =AJ26 -> 186 | K4: =H4*10320 -> 1919520 | N4: 갑 근 세
B5: 잔업수당 | H5: =AJ27 -> 14 | K5: =H5*10320*1.5 -> 216720 | N5: 소 득 세 | T5: =H17*3.3% -> 83218.08
B6: 휴일수당 | K6: =H6*10320*1.5 -> 0 | N6: 건 강 보 험
B7: 특근수당 | H7: =AJ28 -> 24 | K7: =H7*10320*1.5 -> 371520 | N7: 장기요양
B8: 심야수당 | H8: =AJ29 -> 0 | K8: =ROUNDDOWN(H8*10320*1.5,-1) -> 0 | N8: 국 민 연 금
B9: 지각/조퇴 | N9: 공과금
B10: 부서수당 | N10: 가 불 금
B11: 만근수당 | N11: 선지급
B12: 상여금
B13: 간식대 | H13: 14000
N16: 공 제 총 액 | T16: =SUM(T4:Y11) -> 83218.08
B17: 급 여 총 액 | H17: =SUM(K4,K5,K6,K7,K8,K9,H10,H11,H12,H13,H14,H15,H16) -> 2521760 | N17: 실 수 령 액 | T17: =H17-T16 -> 2438541.9
N19: 한 달 동안 수고 많으셨습니다 ^^
P21: 이름 : | T21: 지미경
B24: 이름 | C24: 구분 | D24: 1 | E24: 2 | F24: 3 | G24: 4 | H24: 5 | I24: 6 | J24: 7 | K24: 8 | L24: 9 | M24: 10 | N24: 11 | O24: 12 | P24: 13 | Q24: 14 | R24: 15 | S24: 16 | T24: 17 | U24: 18 | V24: 19 | W24: 20 | X24: 21 | Y24: 22 | Z24: 23 | AA24: 24 | AB24: 25 | AC24: 26 | AD24: 27 | AE24: 28 | AI24: 소급 | AJ24: 합계
D25: 일 | E25: 월 | F25: 화 | G25: 수 | H25: 목 | I25: 금 | J25: 토 | K25: 일 | L25: 월 | M25: 화 | N25: 수 | O25: 목 | P25: 금 | Q25: 토 | R25: 일 | S25: 월 | T25: 화 | U25: 수 | V25: 목 | W25: 금 | X25: 토 | Y25: 일 | Z25: 월 | AA25: 화 | AB25: 수 | AC25: 목 | AD25: 금 | AE25: 토
B26: =T21 -> 지미경 | C26: 기본 | D26: 8 | E26: 8 | F26: 8 | G26: 8 | H26: 8 | I26: 8 | K26: 8 | L26: 8 | M26: 8 | N26: 8 | O26: 8 | P26: 8 | R26: 8 | S26: 8 | T26: 8 | U26: 8 | V26: 8 | W26: 8 | Y26: 8 | Z26: 8 | AA26: 8 | AB26: 2 | AC26: 8 | AD26: 8 | AJ26: =SUM(D26:AI26) -> 186
C27: 연장 | E27: 2 | F27: 2 | G27: 2 | H27: 2 | L27: 2 | M27: 2 | O27: 2 | AJ27: =SUM(D27:AI27) -> 14
C28: 주특 | J28: 8 | X28: 8 | AE28: 8 | AJ28: =SUM(D28:AI28) -> 24
C29: 특잔 | AJ29: =SUM(D29:AI29) -> 0
C30: 심야 | AJ30: =SUM(D30:AI30) -> 0
C31: 근태 | E31: 반차 | P31: 반차 | T31: 설날 | Z31: 연차 | AB31: 조퇴 | AJ31: 계

Sheet 트란티남
B1: 어브코스
B3: 급 여 | N3: 세 액 및 공 제
B4: 기 본 급 | H4: =AJ26 -> 190 | K4: =H4*10320 -> 1960800 | N4: 갑 근 세
B5: 잔업수당 | H5: =AJ27 -> 10 | K5: =H5*10320*1.5 -> 154800 | N5: 소 득 세 | T5: =H17*3.3% -> 86491.68
B6: 휴일수당 | K6: =H6*10320*1.5 -> 0 | N6: 건 강 보 험
B7: 특근수당 | H7: =AJ28 -> 32 | K7: =H7*10320*1.5 -> 495360 | N7: 장기요양
B8: 심야수당 | H8: =AJ29 -> 0 | K8: =ROUNDDOWN(H8*10320*0.5,-1) -> 0 | N8: 국 민 연 금
B9: 지각/조퇴 | N9: 공과금
B10: 부서수당 | N10: 가 불 금
B11: 만근수당 | N11: 선지급
B12: 상여금
B13: 간식대 | H13: 10000
N16: 공 제 총 액 | T16: =SUM(T4:Y11) -> 86491.68
B17: 급 여 총 액 | H17: =SUM(K4,K5,K6,K7,K8,K9,H10,H11,H12,H13,H14,H15,H16) -> 2620960 | N17: 실 수 령 액 | T17: =H17-T16 -> 2534468.3
N19: 한 달 동안 수고 많으셨습니다 ^^
P21: 이름 : | T21: 쩐티남
B24: 이름 | C24: 구분 | D24: 1 | E24: 2 | F24: 3 | G24: 4 | H24: 5 | I24: 6 | J24: 7 | K24: 8 | L24: 9 | M24: 10 | N24: 11 | O24: 12 | P24: 13 | Q24: 14 | R24: 15 | S24: 16 | T24: 17 | U24: 18 | V24: 19 | W24: 20 | X24: 21 | Y24: 22 | Z24: 23 | AA24: 24 | AB24: 25 | AC24: 26 | AD24: 27 | AE24: 28 | AI24: 소급 | AJ24: 합계
D25: 일 | E25: 월 | F25: 화 | G25: 수 | H25: 목 | I25: 금 | J25: 토 | K25: 일 | L25: 월 | M25: 화 | N25: 수 | O25: 목 | P25: 금 | Q25: 토 | R25: 일 | S25: 월 | T25: 화 | U25: 수 | V25: 목 | W25: 금 | X25: 토 | Y25: 일 | Z25: 월 | AA25: 화 | AB25: 수 | AC25: 목 | AD25: 금 | AE25: 토
B26: =T21 -> 쩐티남 | C26: 기본 | D26: 8 | E26: 6 | F26: 8 | G26: 8 | H26: 8 | I26: 8 | K26: 8 | L26: 8 | M26: 8 | N26: 8 | O26: 8 | P26: 8 | R26: 8 | S26: 8 | T26: 8 | U26: 8 | V26: 8 | W26: 8 | Y26: 8 | Z26: 8 | AA26: 8 | AB26: 8 | AC26: 8 | AD26: 8 | AJ26: =SUM(D26:AI26) -> 190
C27: 연장 | F27: 2 | G27: 2 | H27: 2 | M27: 2 | O27: 2 | AJ27: =SUM(D27:AI27) -> 10
C28: 주특 | J28: 8 | Q28: 8 | X28: 8 | AE28: 8 | AJ28: =SUM(D28:AI28) -> 32
C29: 특잔 | AJ29: =SUM(D29:AI29) -> 0
C30: 심야 | AJ30: =SUM(D30:AI30) -> 0
C31: 근태 | T31: 설날 | AJ31: 계

Sheet 박혜선
B1: 어브코스
B3: 급 여 | N3: 세 액 및 공 제
B4: 기 본 급 | H4: =AJ26 -> 158 | K4: =H4*10320 -> 1630560 | N4: 갑 근 세
B5: 잔업수당 | H5: =AJ27 -> 0 | K5: =H5*10320*1.5 -> 0 | N5: 소 득 세 | T5: =H17*3.3% -> 96208.2
B6: 휴일수당 | K6: =H6*10320*1.5 -> 0 | N6: 건 강 보 험
B7: 특근수당 | H7: =AJ28 -> 32 | K7: =H7*10320*1.5 -> 495360 | N7: 장기요양
B8: 심야수당 | H8: =AJ29 -> 51 | K8: =ROUNDDOWN(H8*10320*1.5,-1) -> 789480 | N8: 국 민 연 금
B9: 지각/조퇴 | N9: 공과금
B10: 부서수당 | N10: 가 불 금
B11: 만근수당 | N11: 선지급
B12: 상여금
B13: 간식대
N16: 공 제 총 액 | T16: =SUM(T4:Y11) -> 96208.2
B17: 급 여 총 액 | H17: =SUM(K4,K5,K6,K7,K8,K9,H10,H11,H12,H13,H14,H15,H16) -> 2915400 | N17: 실 수 령 액 | T17: =H17-T16 -> 2819191.8
N19: 한 달 동안 수고 많으셨습니다 ^^
P21: 이름 : | T21: 박혜선
B24: 이름 | C24: 구분 | D24: 1 | E24: 2 | F24: 3 | G24: 4 | H24: 5 | I24: 6 | J24: 7 | K24: 8 | L24: 9 | M24: 10 | N24: 11 | O24: 12 | P24: 13 | Q24: 14 | R24: 15 | S24: 16 | T24: 17 | U24: 18 | V24: 19 | W24: 20 | X24: 21 | Y24: 22 | Z24: 23 | AA24: 24 | AB24: 25 | AC24: 26 | AD24: 27 | AE24: 28 | AI24: 소급 | AJ24: 합계
D25: 일 | E25: 월 | F25: 화 | G25: 수 | H25: 목 | I25: 금 | J25: 토 | K25: 일 | L25: 월 | M25: 화 | N25: 수 | O25: 목 | P25: 금 | Q25: 토 | R25: 일 | S25: 월 | T25: 화 | U25: 수 | V25: 목 | W25: 금 | X25: 토 | Y25: 일 | Z25: 월 | AA25: 화 | AB25: 수 | AC25: 목 | AD25: 금 | AE25: 토
B26: =T21 -> 박혜선 | C26: 기본 | D26: 8 | E26: 6 | F26: 6 | G26: 6 | H26: 6 | I26: 6 | K26: 8 | L26: 6 | M26: 6 | N26: 6 | O26: 6 | P26: 6 | R26: 8 | S26: 8 | T26: 8 | U26: 8 | V26: 6 | W26: 6 | Y26: 8 | Z26: 6 | AA26: 6 | AB26: 6 | AC26: 6 | AD26: 6 | AJ26: =SUM(D26:AI26) -> 158
C27: 연장 | AJ27: =SUM(D27:AI27) -> 0
C28: 주특 | J28: 8 | Q28: 8 | X28: 8 | AE28: 8 | AJ28: =SUM(D28:AI28) -> 32
C29: 수당 | E29: 3 | F29: 3 | G29: 3 | H29: 3 | I29: 3 | L29: 3 | M29: 3 | N29: 3 | O29: 3 | P29: 3 | V29: 3 | W29: 3 | Z29: 3 | AA29: 3 | AB29: 3 | AC29: 3 | AD29: 3 | AJ29: =SUM(D29:AI29) -> 51
C30: 심야 | AJ30: =SUM(D30:AI30) -> 0
C31: 근태 | T31: 설날 | AJ31: 계

Sheet 이수진
B1: 어브코스
B3: 급 여 | N3: 세 액 및 공 제
B4: 기 본 급 | H4: =AJ26 -> 158 | K4: =H4*10320 -> 1630560 | N4: 갑 근 세
B5: 잔업수당 | H5: =AJ27 -> 0 | K5: =H5*10320*1.5 -> 0 | N5: 소 득 세 | T5: =H17*3.3% -> 99376.2
B6: 휴일수당 | K6: =H6*10320*1.5 -> 0 | N6: 건 강 보 험
B7: 특근수당 | H7: =AJ28 -> 32 | K7: =H7*10320*1.5 -> 495360 | N7: 장기요양
B8: 심야수당 | H8: =AJ29 -> 51 | K8: =ROUNDDOWN(H8*10320*1.5,-1) -> 789480 | N8: 국 민 연 금
B9: 지각/조퇴 | N9: 공과금
B10: 부서수당 | N10: 가 불 금
B11: 만근수당 | N11: 선지급
B12: 상여금
B13: 간식대 | H13: 96000
N16: 공 제 총 액 | T16: =SUM(T4:Y11) -> 99376.2
B17: 급 여 총 액 | H17: =SUM(K4,K5,K6,K7,K8,K9,H10,H11,H12,H13,H14,H15,H16) -> 3011400 | N17: 실 수 령 액 | T17: =H17-T16 -> 2912023.8
N19: 한 달 동안 수고 많으셨습니다 ^^
P21: 이름 : | T21: 이수진
B24: 이름 | C24: 구분 | D24: 1 | E24: 2 | F24: 3 | G24: 4 | H24: 5 | I24: 6 | J24: 7 | K24: 8 | L24: 9 | M24: 10 | N24: 11 | O24: 12 | P24: 13 | Q24: 14 | R24: 15 | S24: 16 | T24: 17 | U24: 18 | V24: 19 | W24: 20 | X24: 21 | Y24: 22 | Z24: 23 | AA24: 24 | AB24: 25 | AC24: 26 | AD24: 27 | AE24: 28 | AI24: 소급 | AJ24: 합계
D25: 일 | E25: 월 | F25: 화 | G25: 수 | H25: 목 | I25: 금 | J25: 토 | K25: 일 | L25: 월 | M25: 화 | N25: 수 | O25: 목 | P25: 금 | Q25: 토 | R25: 일 | S25: 월 | T25: 화 | U25: 수 | V25: 목 | W25: 금 | X25: 토 | Y25: 일 | Z25: 월 | AA25: 화 | AB25: 수 | AC25: 목 | AD25: 금 | AE25: 토
B26: =T21 -> 이수진 | C26: 기본 | D26: 8 | E26: 6 | F26: 6 | G26: 6 | H26: 6 | I26: 6 | K26: 8 | L26: 6 | M26: 6 | N26: 6 | O26: 6 | P26: 6 | R26: 8 | S26: 8 | T26: 8 | U26: 8 | V26: 6 | W26: 6 | Y26: 8 | Z26: 6 | AA26: 6 | AB26: 6 | AC26: 6 | AD26: 6 | AJ26: =SUM(D26:AI26) -> 158
C27: 연장 | AJ27: =SUM(D27:AI27) -> 0
C28: 주특 | J28: 8 | Q28: 8 | X28: 8 | AE28: 8 | AJ28: =SUM(D28:AI28) -> 32
C29: 수당 | E29: 3 | F29: 3 | G29: 3 | H29: 3 | I29: 3 | L29: 3 | M29: 3 | N29: 3 | O29: 3 | P29: 3 | V29: 3 | W29: 3 | Z29: 3 | AA29: 3 | AB29: 3 | AC29: 3 | AD29: 3 | AJ29: =SUM(D29:AI29) -> 51
C30: 심야 | AJ30: =SUM(D30:AI30) -> 0
C31: 근태 | E31: 연차 | T31: 설날 | AJ31: 계

Sheet 강명옥
B1: 어브코스
B3: 급 여 | N3: 세 액 및 공 제
B4: 기 본 급 | H4: =AJ26 -> 174 | K4: =H4*10320 -> 1795680 | N4: 갑 근 세
B5: 잔업수당 | H5: =AJ27 -> 10 | K5: =H5*10320*1.5 -> 154800 | N5: 소 득 세 | T5: =H17*3.3% -> 76956
B6: 휴일수당 | K6: =H6*10320*1.5 -> 0 | N6: 건 강 보 험
B7: 특근수당 | H7: =AJ28 -> 24 | K7: =H7*10320*1.5 -> 371520 | N7: 장기요양
B8: 심야수당 | H8: =AJ29 -> 0 | K8: =ROUNDDOWN(H8*10320*0.5,-1) -> 0 | N8: 국 민 연 금
B9: 지각/조퇴 | N9: 공과금
B10: 부서수당 | N10: 가 불 금
B11: 만근수당 | N11: 선지급
B12: 상여금
B13: 간식대 | H13: 10000
N16: 공 제 총 액 | T16: =SUM(T4:Y11) -> 76956
B17: 급 여 총 액 | H17: =SUM(K4,K5,K6,K7,K8,K9,H10,H11,H12,H13,H14,H15,H16) -> 2332000 | N17: 실 수 령 액 | T17: =H17-T16 -> 2255044
N19: 한 달 동안 수고 많으셨습니다 ^^
P21: 이름 : | T21: 강명옥
B24: 이름 | C24: 구분 | D24: 1 | E24: 2 | F24: 3 | G24: 4 | H24: 5 | I24: 6 | J24: 7 | K24: 8 | L24: 9 | M24: 10 | N24: 11 | O24: 12 | P24: 13 | Q24: 14 | R24: 15 | S24: 16 | T24: 17 | U24: 18 | V24: 19 | W24: 20 | X24: 21 | Y24: 22 | Z24: 23 | AA24: 24 | AB24: 25 | AC24: 26 | AD24: 27 | AE24: 28 | AI24: 소급 | AJ24: 합계
D25: 일 | E25: 월 | F25: 화 | G25: 수 | H25: 목 | I25: 금 | J25: 토 | K25: 일 | L25: 월 | M25: 화 | N25: 수 | O25: 목 | P25: 금 | Q25: 토 | R25: 일 | S25: 월 | T25: 화 | U25: 수 | V25: 목 | W25: 금 | X25: 토 | Y25: 일 | Z25: 월 | AA25: 화 | AB25: 수 | AC25: 목 | AD25: 금 | AE25: 토
B26: =T21 -> 강명옥 | C26: 기본 | D26: 8 | E26: 6 | F26: 8 | G26: 8 | H26: 8 | I26: 8 | K26: 8 | L26: 8 | M26: 8 | N26: 8 | P26: 8 | S26: 8 | T26: 8 | U26: 8 | V26: 8 | W26: 8 | Y26: 8 | Z26: 8 | AA26: 8 | AB26: 8 | AC26: 8 | AD26: 8 | AJ26: =SUM(D26:AI26) -> 174
C27: 연장 | F27: 2 | G27: 2 | H27: 2 | L27: 2 | M27: 2 | AJ27: =SUM(D27:AI27) -> 10
C28: 주특 | J28: 8 | Q28: 8 | X28: 8 | AJ28: =SUM(D28:AI28) -> 24
C29: 특잔 | AJ29: =SUM(D29:AI29) -> 0
C30: 심야 | AJ30: =SUM(D30:AI30) -> 0
C31: 근태 | O31: 결근 | T31: 설날 | AJ31: 계

Sheet 최춘자
B1: 어브코스
B3: 급 여 | N3: 세 액 및 공 제
B4: 기 본 급 | H4: =AJ26 -> 158 | K4: =H4*10320 -> 1630560 | N4: 갑 근 세
B5: 잔업수당 | H5: =AJ27 -> 0 | K5: =H5*10320*1.5 -> 0 | N5: 소 득 세 | T5: =H17*3.3% -> 91004.76
B6: 휴일수당 | K6: =H6*10320*1.5 -> 0 | N6: 건 강 보 험
B7: 특근수당 | H7: =AJ28 -> 16 | K7: =H7*10320*1.5 -> 247680 | N7: 장기요양
B8: 심야수당 | H8: =AJ29 -> 51 | K8: =ROUNDDOWN(H8*10320*1.5,-1) -> 789480 | N8: 국 민 연 금
B9: 지각/조퇴 | N9: 공과금
B10: 부서수당 | N10: 가 불 금
B11: 만근수당 | N11: 선지급
B12: 상여금
B13: 간식대 | H13: 90000
N16: 공 제 총 액 | T16: =SUM(T4:Y11) -> 91004.76
B17: 급 여 총 액 | H17: =SUM(K4,K5,K6,K7,K8,K9,H10,H11,H12,H13,H14,H15,H16) -> 2757720 | N17: 실 수 령 액 | T17: =H17-T16 -> 2666715.2
N19: 한 달 동안 수고 많으셨습니다 ^^
P21: 이름 : | T21: 최춘자
